============================= test session starts ==============================
platform linux -- Python 3.11.6, pytest-8.4.2, pluggy-1.6.0 -- /opt/computersetup/.pyenv/versions/3.11.6/bin/python
cachedir: .pytest_cache
rootdir: /home/ubuntu/code_artifacts/solo-git
configfile: pytest.ini
plugins: asyncio-1.2.0, cov-7.0.0, anyio-4.10.0
asyncio: mode=Mode.STRICT, debug=False, asyncio_default_fixture_loop_scope=None, asyncio_default_test_loop_scope=function
collecting ... collected 392 items

tests/test_ai_orchestrator.py::test_orchestrator_initialization PASSED   [  0%]
tests/test_ai_orchestrator.py::test_plan_simple_task PASSED              [  0%]
tests/test_ai_orchestrator.py::test_plan_complex_task PASSED             [  0%]
tests/test_ai_orchestrator.py::test_plan_with_context PASSED             [  1%]
tests/test_ai_orchestrator.py::test_plan_budget_exceeded PASSED          [  1%]
tests/test_ai_orchestrator.py::test_generate_patch PASSED                [  1%]
tests/test_ai_orchestrator.py::test_generate_patch_with_files PASSED     [  1%]
tests/test_ai_orchestrator.py::test_review_patch PASSED                  [  2%]
tests/test_ai_orchestrator.py::test_review_large_patch PASSED            [  2%]
tests/test_ai_orchestrator.py::test_review_patch_without_tests PASSED    [  2%]
tests/test_ai_orchestrator.py::test_diagnose_failure PASSED              [  2%]
tests/test_ai_orchestrator.py::test_get_status PASSED                    [  3%]
tests/test_ai_orchestrator.py::test_force_model_selection PASSED         [  3%]
tests/test_ai_orchestrator.py::test_model_escalation_on_failure PASSED   [  3%]
tests/test_ai_orchestrator.py::test_find_model_by_name PASSED            [  3%]
tests/test_ai_orchestrator.py::test_find_model_by_name_not_found PASSED  [  4%]
tests/test_ai_orchestrator_enhanced.py::test_plan_with_force_model PASSED [  4%]
tests/test_ai_orchestrator_enhanced.py::test_plan_with_invalid_force_model PASSED [  4%]
tests/test_ai_orchestrator_enhanced.py::test_plan_budget_exceeded PASSED [  4%]
tests/test_ai_orchestrator_enhanced.py::test_plan_with_repo_context PASSED [  5%]
tests/test_ai_orchestrator_enhanced.py::test_plan_escalation_on_failure PASSED [  5%]
tests/test_ai_orchestrator_enhanced.py::test_plan_escalation_budget_check PASSED [  5%]
tests/test_ai_orchestrator_enhanced.py::test_generate_patch_with_force_model PASSED [  5%]
tests/test_ai_orchestrator_enhanced.py::test_generate_patch_invalid_force_model PASSED [  6%]
tests/test_ai_orchestrator_enhanced.py::test_generate_patch_low_complexity PASSED [  6%]
tests/test_ai_orchestrator_enhanced.py::test_generate_patch_high_complexity PASSED [  6%]
tests/test_ai_orchestrator_enhanced.py::test_generate_patch_with_file_contents PASSED [  6%]
tests/test_ai_orchestrator_enhanced.py::test_generate_patch_budget_exceeded PASSED [  7%]
tests/test_ai_orchestrator_enhanced.py::test_generate_patch_escalation_on_failure PASSED [  7%]
tests/test_ai_orchestrator_enhanced.py::test_generate_patch_escalation_budget_check PASSED [  7%]
tests/test_ai_orchestrator_enhanced.py::test_review_patch_large_patch PASSED [  7%]
tests/test_ai_orchestrator_enhanced.py::test_review_patch_no_tests PASSED [  8%]
tests/test_ai_orchestrator_enhanced.py::test_review_patch_with_tests PASSED [  8%]
tests/test_ai_orchestrator_enhanced.py::test_review_patch_with_context PASSED [  8%]
tests/test_ai_orchestrator_enhanced.py::test_diagnose_failure PASSED     [  8%]
tests/test_ai_orchestrator_enhanced.py::test_diagnose_failure_with_context PASSED [  9%]
tests/test_ai_orchestrator_enhanced.py::test_get_status PASSED           [  9%]
tests/test_ai_orchestrator_enhanced.py::test_find_model_by_name_found PASSED [  9%]
tests/test_ai_orchestrator_enhanced.py::test_find_model_by_name_not_found PASSED [  9%]
tests/test_ai_orchestrator_enhanced.py::test_task_type_enum PASSED       [ 10%]
tests/test_ai_orchestrator_enhanced.py::test_plan_response_dataclass PASSED [ 10%]
tests/test_ai_orchestrator_enhanced.py::test_patch_response_dataclass PASSED [ 10%]
tests/test_ai_orchestrator_enhanced.py::test_review_response_dataclass PASSED [ 10%]
tests/test_ai_orchestrator_enhanced.py::test_orchestrator_initialization_with_custom_config PASSED [ 11%]
tests/test_ai_orchestrator_enhanced.py::test_generate_patch_empty_file_contents PASSED [ 11%]
tests/test_ai_orchestrator_enhanced.py::test_diagnose_failure_long_output PASSED [ 11%]
tests/test_code_generator.py::test_generator_initialization PASSED       [ 11%]
tests/test_code_generator.py::test_generate_patch_mock PASSED            [ 12%]
tests/test_code_generator.py::test_generated_patch_str PASSED            [ 12%]
tests/test_code_generator.py::test_extract_diff_from_markdown PASSED     [ 12%]
tests/test_code_generator.py::test_extract_files_from_diff PASSED        [ 13%]
tests/test_code_generator.py::test_count_changes PASSED                  [ 13%]
tests/test_code_generator.py::test_generate_mock_patch_create PASSED     [ 13%]
tests/test_code_generator.py::test_generate_mock_patch_modify PASSED     [ 13%]
tests/test_code_generator.py::test_generate_mock_patch_delete PASSED     [ 14%]
tests/test_code_generator.py::test_create_fallback_patch PASSED          [ 14%]
tests/test_code_generator.py::test_generate_patch_with_file_contents PASSED [ 14%]
tests/test_code_generator.py::test_generate_patch_from_feedback PASSED   [ 14%]
tests/test_code_generator_enhanced.py::test_generated_patch_str PASSED   [ 15%]
tests/test_code_generator_enhanced.py::test_generate_patch_with_file_contents PASSED [ 15%]
tests/test_code_generator_enhanced.py::test_generate_patch_with_deployment_credentials PASSED [ 15%]
tests/test_code_generator_enhanced.py::test_generate_patch_api_error_fallback PASSED [ 15%]
tests/test_code_generator_enhanced.py::test_extract_diff_with_markdown_diff PASSED [ 16%]
tests/test_code_generator_enhanced.py::test_extract_diff_with_plain_markdown PASSED [ 16%]
tests/test_code_generator_enhanced.py::test_extract_diff_no_markdown PASSED [ 16%]
tests/test_code_generator_enhanced.py::test_extract_diff_with_surrounding_text PASSED [ 16%]
tests/test_code_generator_enhanced.py::test_extract_diff_no_markers PASSED [ 17%]
tests/test_code_generator_enhanced.py::test_extract_files_from_diff PASSED [ 17%]
tests/test_code_generator_enhanced.py::test_extract_files_from_diff_with_dev_null PASSED [ 17%]
tests/test_code_generator_enhanced.py::test_extract_files_from_diff_deletion PASSED [ 17%]
tests/test_code_generator_enhanced.py::test_count_changes_additions_deletions PASSED [ 18%]
tests/test_code_generator_enhanced.py::test_count_changes_ignores_headers PASSED [ 18%]
tests/test_code_generator_enhanced.py::test_generate_mock_patch_create PASSED [ 18%]
tests/test_code_generator_enhanced.py::test_generate_mock_patch_modify PASSED [ 18%]
tests/test_code_generator_enhanced.py::test_generate_mock_patch_delete PASSED [ 19%]
tests/test_code_generator_enhanced.py::test_generate_mock_patch_multiple_files PASSED [ 19%]
tests/test_code_generator_enhanced.py::test_create_fallback_patch PASSED [ 19%]
tests/test_code_generator_enhanced.py::test_generate_patch_from_feedback PASSED [ 19%]
tests/test_code_generator_enhanced.py::test_generate_patch_with_long_file_content PASSED [ 20%]
tests/test_code_generator_enhanced.py::test_generate_patch_without_file_contents PASSED [ 20%]
tests/test_code_generator_enhanced.py::test_extract_files_duplicate_handling PASSED [ 20%]
tests/test_code_generator_enhanced.py::test_generate_mock_patch_with_file_contents PASSED [ 20%]
tests/test_code_generator_enhanced.py::test_generate_patch_model_parameter PASSED [ 21%]
tests/test_code_generator_enhanced.py::test_generate_patch_confidence_value PASSED [ 21%]
tests/test_code_generator_enhanced.py::test_count_changes_empty_diff PASSED [ 21%]
tests/test_code_generator_enhanced.py::test_extract_files_empty_diff PASSED [ 21%]
tests/test_core.py::test_repository_creation PASSED                      [ 22%]
tests/test_core.py::test_repository_to_dict PASSED                       [ 22%]
tests/test_core.py::test_repository_from_dict PASSED                     [ 22%]
tests/test_core.py::test_workpad_creation PASSED                         [ 22%]
tests/test_core.py::test_workpad_to_dict PASSED                          [ 23%]
tests/test_core.py::test_workpad_from_dict PASSED                        [ 23%]
tests/test_core.py::test_checkpoint_creation PASSED                      [ 23%]
tests/test_core_100_percent.py::TestRepositoryComplete::test_repository_path_conversion PASSED [ 23%]
tests/test_core_100_percent.py::TestCheckpointComplete::test_checkpoint_to_dict PASSED [ 24%]
tests/test_core_100_percent.py::TestCheckpointComplete::test_checkpoint_from_dict PASSED [ 24%]
tests/test_cost_guard.py::test_tracker_initialization PASSED             [ 24%]
tests/test_cost_guard.py::test_record_usage PASSED                       [ 25%]
tests/test_cost_guard.py::test_record_multiple_usage PASSED              [ 25%]
tests/test_cost_guard.py::test_track_by_model PASSED                     [ 25%]
tests/test_cost_guard.py::test_track_by_task PASSED                      [ 25%]
tests/test_cost_guard.py::test_persistence PASSED                        [ 26%]
tests/test_cost_guard.py::test_check_budget_within_limit PASSED          [ 26%]
tests/test_cost_guard.py::test_check_budget_exceeds_limit PASSED         [ 26%]
tests/test_cost_guard.py::test_budget_alert_threshold PASSED             [ 26%]
tests/test_cost_guard.py::test_get_remaining_budget PASSED               [ 27%]
tests/test_cost_guard.py::test_record_usage_through_guard PASSED         [ 27%]
tests/test_cost_guard.py::test_get_status PASSED                         [ 27%]
tests/test_cost_guard.py::test_daily_usage_serialization PASSED          [ 27%]
tests/test_cost_guard.py::test_weekly_stats PASSED                       [ 28%]
tests/test_cost_guard_enhanced.py::test_load_history_corrupted_file PASSED [ 28%]
tests/test_cost_guard_enhanced.py::test_load_history_empty_file PASSED   [ 28%]
tests/test_cost_guard_enhanced.py::test_save_history_error_handling PASSED [ 28%]
tests/test_cost_guard_enhanced.py::test_record_usage_day_rollover PASSED [ 29%]
tests/test_cost_guard_enhanced.py::test_record_usage_new_day PASSED      [ 29%]
tests/test_cost_guard_enhanced.py::test_get_today_tokens_no_usage PASSED [ 29%]
tests/test_cost_guard_enhanced.py::test_get_today_cost_no_usage PASSED   [ 29%]
tests/test_cost_guard_enhanced.py::test_get_usage_breakdown_no_usage PASSED [ 30%]
tests/test_cost_guard_enhanced.py::test_get_weekly_stats PASSED          [ 30%]
tests/test_cost_guard_enhanced.py::test_check_budget_alert_threshold PASSED [ 30%]
tests/test_cost_guard_enhanced.py::test_daily_usage_to_dict PASSED       [ 30%]
tests/test_cost_guard_enhanced.py::test_daily_usage_from_dict PASSED     [ 31%]
tests/test_cost_guard_enhanced.py::test_daily_usage_from_dict_no_breakdowns PASSED [ 31%]
tests/test_cost_guard_enhanced.py::test_cost_guard_get_status PASSED     [ 31%]
tests/test_cost_guard_enhanced.py::test_tracker_persistence PASSED       [ 31%]
tests/test_cost_guard_enhanced.py::test_multiple_models_tracking PASSED  [ 32%]
tests/test_cost_guard_enhanced.py::test_multiple_tasks_tracking PASSED   [ 32%]
tests/test_cost_guard_enhanced.py::test_budget_config_defaults PASSED    [ 32%]
tests/test_cost_guard_enhanced.py::test_cost_calculation PASSED          [ 32%]
tests/test_cost_guard_enhanced.py::test_zero_cost_usage PASSED           [ 33%]
tests/test_git_engine.py::test_init_from_zip PASSED                      [ 33%]
tests/test_git_engine.py::test_create_workpad PASSED                     [ 33%]
tests/test_git_engine.py::test_list_repos PASSED                         [ 33%]
tests/test_git_engine.py::test_list_workpads PASSED                      [ 34%]
tests/test_git_engine.py::test_workpad_not_found PASSED                  [ 34%]
tests/test_git_engine.py::test_repository_not_found PASSED               [ 34%]
tests/test_git_engine.py::test_can_promote PASSED                        [ 34%]
tests/test_git_engine.py::test_metadata_persistence PASSED               [ 35%]
tests/test_git_engine_100_percent.py::TestGitEngineErrorHandling::test_init_from_zip_invalid_zip PASSED [ 35%]
tests/test_git_engine_100_percent.py::TestGitEngineErrorHandling::test_init_from_zip_empty_name PASSED [ 35%]
tests/test_git_engine_100_percent.py::TestGitEngineErrorHandling::test_init_from_git_invalid_url FAILED [ 35%]
tests/test_git_engine_100_percent.py::TestGitEngineErrorHandling::test_init_from_git_empty_url PASSED [ 36%]
tests/test_git_engine_100_percent.py::TestGitEngineErrorHandling::test_create_workpad_long_title FAILED [ 36%]
tests/test_git_engine_100_percent.py::TestGitEngineErrorHandling::test_create_workpad_repository_error FAILED [ 36%]
tests/test_git_engine_100_percent.py::TestGitEngineErrorHandling::test_apply_patch_git_error PASSED [ 36%]
tests/test_git_engine_100_percent.py::TestGitEngineErrorHandling::test_promote_workpad_error FAILED [ 37%]
tests/test_git_engine_100_percent.py::TestGitEngineErrorHandling::test_revert_last_commit_error FAILED [ 37%]
tests/test_git_engine_100_percent.py::TestGitEngineErrorHandling::test_get_diff_error FAILED [ 37%]
tests/test_git_engine_100_percent.py::TestGitEngineErrorHandling::test_get_history_error PASSED [ 38%]
tests/test_git_engine_100_percent.py::TestGitEngineErrorHandling::test_get_status_error PASSED [ 38%]
tests/test_git_engine_100_percent.py::TestGitEngineErrorHandling::test_get_file_content_error PASSED [ 38%]
tests/test_git_engine_100_percent.py::TestGitEngineErrorHandling::test_rollback_to_checkpoint_error FAILED [ 38%]
tests/test_git_engine_100_percent.py::TestGitEngineErrorHandling::test_delete_workpad_error PASSED [ 39%]
tests/test_git_engine_100_percent.py::TestGitEngineErrorHandling::test_get_workpad_stats_error PASSED [ 39%]
tests/test_git_engine_100_percent.py::TestGitEngineErrorHandling::test_list_branches_error PASSED [ 39%]
tests/test_git_engine_100_percent.py::TestGitEngineErrorHandling::test_list_tags_error PASSED [ 39%]
tests/test_git_engine_100_percent.py::TestGitEngineErrorHandling::test_create_commit_error PASSED [ 40%]
tests/test_git_engine_100_percent.py::TestGitEngineErrorHandling::test_get_commits_ahead_behind_error PASSED [ 40%]
tests/test_git_engine_100_percent.py::TestGitEngineErrorHandling::test_list_files_error PASSED [ 40%]
tests/test_git_engine_100_percent.py::TestGitEngineErrorHandling::test_switch_workpad_error PASSED [ 40%]
tests/test_git_engine_100_percent.py::TestGitEngineErrorHandling::test_compare_workpads_error FAILED [ 41%]
tests/test_git_engine_100_percent.py::TestGitEngineErrorHandling::test_get_workpad_merge_preview_error PASSED [ 41%]
tests/test_git_engine_100_percent.py::TestGitEngineEdgeCases::test_get_active_workpad_on_trunk PASSED [ 41%]
tests/test_git_engine_100_percent.py::TestGitEngineEdgeCases::test_get_active_workpad_error PASSED [ 41%]
tests/test_git_engine_100_percent.py::TestGitEngineEdgeCases::test_can_promote_false PASSED [ 42%]
tests/test_git_engine_100_percent.py::TestGitEngineEdgeCases::test_can_promote_error_returns_false PASSED [ 42%]
tests/test_git_engine_extended.py::test_get_history PASSED               [ 42%]
tests/test_git_engine_extended.py::test_get_history_with_multiple_commits PASSED [ 42%]
tests/test_git_engine_extended.py::test_get_history_invalid_repo PASSED  [ 43%]
tests/test_git_engine_extended.py::test_get_status_clean_repo PASSED     [ 43%]
tests/test_git_engine_extended.py::test_get_status_invalid_repo PASSED   [ 43%]
tests/test_git_engine_extended.py::test_get_file_content PASSED          [ 43%]
tests/test_git_engine_extended.py::test_get_file_content_from_subdirectory PASSED [ 44%]
tests/test_git_engine_extended.py::test_get_file_content_invalid_file PASSED [ 44%]
tests/test_git_engine_extended.py::test_rollback_to_checkpoint PASSED    [ 44%]
tests/test_git_engine_extended.py::test_rollback_invalid_checkpoint PASSED [ 44%]
tests/test_git_engine_extended.py::test_delete_workpad PASSED            [ 45%]
tests/test_git_engine_extended.py::test_delete_workpad_with_checkpoints PASSED [ 45%]
tests/test_git_engine_extended.py::test_get_workpad_stats PASSED         [ 45%]
tests/test_git_engine_extended.py::test_cleanup_stale_workpads PASSED    [ 45%]
tests/test_git_engine_extended.py::test_cleanup_preserves_recent_workpads PASSED [ 46%]
tests/test_git_engine_extended.py::test_list_branches PASSED             [ 46%]
tests/test_git_engine_extended.py::test_list_tags PASSED                 [ 46%]
tests/test_git_engine_extended.py::test_create_commit PASSED             [ 46%]
tests/test_git_engine_extended.py::test_get_commits_ahead_behind PASSED  [ 47%]
tests/test_git_engine_extended.py::test_list_files PASSED                [ 47%]
tests/test_git_engine_extended.py::test_init_from_zip_empty_name PASSED  [ 47%]
tests/test_git_engine_extended.py::test_init_from_zip_empty_buffer PASSED [ 47%]
tests/test_git_engine_extended.py::test_init_from_zip_long_name PASSED   [ 48%]
tests/test_git_engine_extended.py::test_create_workpad_empty_title PASSED [ 48%]
tests/test_git_engine_extended.py::test_create_workpad_long_title PASSED [ 48%]
tests/test_git_engine_extended.py::test_apply_patch_empty_patch PASSED   [ 48%]
tests/test_git_engine_extended.py::test_validate_repo_id PASSED          [ 49%]
tests/test_git_engine_extended.py::test_validate_pad_id PASSED           [ 49%]
tests/test_git_engine_extended.py::test_full_workflow_with_new_features PASSED [ 49%]
tests/test_git_engine_extended.py::test_error_recovery_workflow PASSED   [ 50%]
tests/test_model_router.py::test_router_initialization PASSED            [ 50%]
tests/test_model_router.py::test_load_models PASSED                      [ 50%]
tests/test_model_router.py::test_analyze_complexity_simple PASSED        [ 50%]
tests/test_model_router.py::test_analyze_complexity_security PASSED      [ 51%]
tests/test_model_router.py::test_analyze_complexity_architecture PASSED  [ 51%]
tests/test_model_router.py::test_select_model_simple PASSED              [ 51%]
tests/test_model_router.py::test_select_model_complex PASSED             [ 51%]
tests/test_model_router.py::test_select_model_forced_tier PASSED         [ 52%]
tests/test_model_router.py::test_select_model_low_budget PASSED          [ 52%]
tests/test_model_router.py::test_estimate_patch_size PASSED              [ 52%]
tests/test_model_router.py::test_escalate_model PASSED                   [ 52%]
tests/test_model_router.py::test_escalate_from_planning PASSED           [ 53%]
tests/test_model_router.py::test_complexity_score_calculation PASSED     [ 53%]
tests/test_model_router_enhanced.py::test_model_config_str PASSED        [ 53%]
tests/test_model_router_enhanced.py::test_complexity_metrics_str PASSED  [ 53%]
tests/test_model_router_enhanced.py::test_analyze_complexity_with_file_count PASSED [ 54%]
tests/test_model_router_enhanced.py::test_analyze_complexity_multiple_files_keywords PASSED [ 54%]
tests/test_model_router_enhanced.py::test_analyze_complexity_with_tests PASSED [ 54%]
tests/test_model_router_enhanced.py::test_analyze_complexity_spec_keyword PASSED [ 54%]
tests/test_model_router_enhanced.py::test_estimate_patch_size_with_keywords PASSED [ 55%]
tests/test_model_router_enhanced.py::test_estimate_patch_size_capped PASSED [ 55%]
tests/test_model_router_enhanced.py::test_select_tier_security_sensitive PASSED [ 55%]
tests/test_model_router_enhanced.py::test_select_tier_architecture PASSED [ 55%]
tests/test_model_router_enhanced.py::test_select_tier_large_patch PASSED [ 56%]
tests/test_model_router_enhanced.py::test_select_tier_high_complexity_score PASSED [ 56%]
tests/test_model_router_enhanced.py::test_select_tier_medium_complexity PASSED [ 56%]
tests/test_model_router_enhanced.py::test_select_tier_low_complexity PASSED [ 56%]
tests/test_model_router_enhanced.py::test_get_model_for_tier_no_models PASSED [ 57%]
tests/test_model_router_enhanced.py::test_get_model_for_tier_low_budget_multiple_models PASSED [ 57%]
tests/test_model_router_enhanced.py::test_escalate_from_coding PASSED    [ 57%]
tests/test_model_router_enhanced.py::test_complexity_score_components PASSED [ 57%]
tests/test_model_router_enhanced.py::test_all_security_keywords PASSED   [ 58%]
tests/test_model_router_enhanced.py::test_all_architecture_keywords PASSED [ 58%]
tests/test_patch_engine.py::test_parse_affected_files PASSED             [ 58%]
tests/test_patch_engine.py::test_patch_validation_no_conflicts PASSED    [ 58%]
tests/test_patch_engine_100_percent.py::TestPatchEngineErrorHandling::test_apply_patch_git_engine_error PASSED [ 59%]
tests/test_patch_engine_100_percent.py::TestPatchEngineErrorHandling::test_validate_patch_workpad_not_found PASSED [ 59%]
tests/test_patch_engine_100_percent.py::TestPatchEngineErrorHandling::test_validate_patch_permission_error PASSED [ 59%]
tests/test_patch_engine_100_percent.py::TestPatchEngineErrorHandling::test_detect_conflicts_no_conflicts PASSED [ 59%]
tests/test_patch_engine_100_percent.py::TestPatchComplexityCalculation::test_complexity_moderate PASSED [ 60%]
tests/test_patch_engine_100_percent.py::TestPatchComplexityCalculation::test_complexity_complex PASSED [ 60%]
tests/test_patch_engine_100_percent.py::TestPatchComplexityCalculation::test_complexity_very_complex PASSED [ 60%]
tests/test_patch_engine_100_percent.py::TestApplicationRecommendations::test_recommendation_moderate_complexity PASSED [ 60%]
tests/test_patch_engine_100_percent.py::TestApplicationRecommendations::test_recommendation_high_complexity PASSED [ 61%]
tests/test_patch_engine_100_percent.py::TestApplicationRecommendations::test_recommendation_very_high_complexity PASSED [ 61%]
tests/test_patch_engine_100_percent.py::TestPatchSyntaxValidation::test_validate_patch_syntax_no_hunks PASSED [ 61%]
tests/test_patch_engine_100_percent.py::TestCreatePatchFromFiles::test_create_patch_success PASSED [ 61%]
tests/test_patch_engine_100_percent.py::TestCreatePatchFromFiles::test_create_patch_workpad_not_found PASSED [ 62%]
tests/test_patch_engine_100_percent.py::TestCreatePatchFromFiles::test_create_patch_repo_error FAILED [ 62%]
tests/test_patch_engine_100_percent.py::TestApplyPatchInteractive::test_apply_patch_interactive_application_failed PASSED [ 62%]
tests/test_patch_engine_100_percent.py::TestPatchEngineIntegration::test_full_patch_workflow_with_all_features PASSED [ 63%]
tests/test_patch_engine_enhanced.py::test_get_patch_stats_simple PASSED  [ 63%]
tests/test_patch_engine_enhanced.py::test_get_patch_stats_complex PASSED [ 63%]
tests/test_patch_engine_enhanced.py::test_patch_complexity_calculation PASSED [ 63%]
tests/test_patch_engine_enhanced.py::test_preview_patch_success PASSED   [ 64%]
tests/test_patch_engine_enhanced.py::test_preview_patch_with_conflicts PASSED [ 64%]
tests/test_patch_engine_enhanced.py::test_detect_conflicts_detailed_no_conflicts PASSED [ 64%]
tests/test_patch_engine_enhanced.py::test_detect_conflicts_detailed_with_conflicts PASSED [ 64%]
tests/test_patch_engine_enhanced.py::test_split_patch_by_file PASSED     [ 65%]
tests/test_patch_engine_enhanced.py::test_combine_patches PASSED         [ 65%]
tests/test_patch_engine_enhanced.py::test_combine_patches_empty PASSED   [ 65%]
tests/test_patch_engine_enhanced.py::test_validate_patch_syntax_valid PASSED [ 65%]
tests/test_patch_engine_enhanced.py::test_validate_patch_syntax_empty PASSED [ 66%]
tests/test_patch_engine_enhanced.py::test_validate_patch_syntax_missing_headers PASSED [ 66%]
tests/test_patch_engine_enhanced.py::test_apply_patch_interactive_dry_run PASSED [ 66%]
tests/test_patch_engine_enhanced.py::test_apply_patch_interactive_success PASSED [ 66%]
tests/test_patch_engine_enhanced.py::test_apply_patch_interactive_invalid_syntax PASSED [ 67%]
tests/test_patch_engine_enhanced.py::test_apply_patch_interactive_with_conflicts PASSED [ 67%]
tests/test_patch_engine_enhanced.py::test_patch_stats_with_file_creation PASSED [ 67%]
tests/test_patch_engine_enhanced.py::test_patch_stats_with_file_deletion PASSED [ 67%]
tests/test_phase3_enhanced_mocks.py::TestAutoMergeWorkflowMocked::test_execute_with_green_tests_and_auto_promote PASSED [ 68%]
tests/test_phase3_enhanced_mocks.py::TestAutoMergeWorkflowMocked::test_execute_with_red_tests_no_promote PASSED [ 68%]
tests/test_phase3_enhanced_mocks.py::TestAutoMergeWorkflowMocked::test_execute_with_test_failure_shows_patterns PASSED [ 68%]
tests/test_phase3_enhanced_mocks.py::TestAutoMergeWorkflowMocked::test_execute_without_auto_promote PASSED [ 68%]
tests/test_phase3_enhanced_mocks.py::TestAutoMergeWorkflowMocked::test_format_result_success PASSED [ 69%]
tests/test_phase3_enhanced_mocks.py::TestAutoMergeWorkflowMocked::test_format_result_failure PASSED [ 69%]
tests/test_phase3_enhanced_mocks.py::TestCIOrchestratorMocked::test_run_smoke_tests_all_pass PASSED [ 69%]
tests/test_phase3_enhanced_mocks.py::TestCIOrchestratorMocked::test_run_smoke_tests_with_failures PASSED [ 69%]
tests/test_phase3_enhanced_mocks.py::TestCIOrchestratorMocked::test_run_smoke_tests_with_timeouts PASSED [ 70%]
tests/test_phase3_enhanced_mocks.py::TestCIOrchestratorMocked::test_run_smoke_tests_repo_not_found PASSED [ 70%]
tests/test_phase3_enhanced_mocks.py::TestCIOrchestratorMocked::test_format_result_success PASSED [ 70%]
tests/test_phase3_enhanced_mocks.py::TestCIOrchestratorMocked::test_format_result_failure PASSED [ 70%]
tests/test_phase3_enhanced_mocks.py::TestIntegrationWorkflow::test_full_workflow_green_path PASSED [ 71%]
tests/test_phase3_enhanced_mocks.py::TestIntegrationWorkflow::test_full_workflow_red_path PASSED [ 71%]
tests/test_phase3_workflows.py::TestAutoMergeWorkflow::test_workflow_initialization ERROR [ 71%]
tests/test_phase3_workflows.py::TestAutoMergeWorkflow::test_workflow_with_custom_rules ERROR [ 71%]
tests/test_phase3_workflows.py::TestAutoMergeWorkflow::test_execute_nonexistent_workpad ERROR [ 72%]
tests/test_phase3_workflows.py::TestAutoMergeWorkflow::test_format_result ERROR [ 72%]
tests/test_phase3_workflows.py::TestCIOrchestrator::test_orchestrator_initialization ERROR [ 72%]
tests/test_phase3_workflows.py::TestCIOrchestrator::test_run_smoke_tests_nonexistent_repo ERROR [ 72%]
tests/test_phase3_workflows.py::TestCIOrchestrator::test_ci_result_is_green PASSED [ 73%]
tests/test_phase3_workflows.py::TestCIOrchestrator::test_ci_result_is_red PASSED [ 73%]
tests/test_phase3_workflows.py::TestCIOrchestrator::test_format_ci_result ERROR [ 73%]
tests/test_phase3_workflows.py::TestRollbackHandler::test_handler_initialization PASSED [ 73%]
tests/test_phase3_workflows.py::TestRollbackHandler::test_handle_passing_ci PASSED [ 74%]
tests/test_phase3_workflows.py::TestRollbackHandler::test_handle_failed_ci_nonexistent_repo PASSED [ 74%]
tests/test_phase3_workflows.py::TestRollbackHandler::test_format_rollback_result PASSED [ 74%]
tests/test_phase3_workflows.py::TestPhase3Integration::test_ci_status_enum PASSED [ 75%]
tests/test_phase3_workflows.py::TestPhase3Integration::test_auto_merge_result_dataclass PASSED [ 75%]
tests/test_phase3_workflows.py::TestPhase3Integration::test_rollback_result_dataclass PASSED [ 75%]
tests/test_planning_engine.py::test_engine_initialization PASSED         [ 75%]
tests/test_planning_engine.py::test_generate_plan_mock PASSED            [ 76%]
tests/test_planning_engine.py::test_generate_plan_with_context PASSED    [ 76%]
tests/test_planning_engine.py::test_file_change_creation PASSED          [ 76%]
tests/test_planning_engine.py::test_code_plan_to_dict PASSED             [ 76%]
tests/test_planning_engine.py::test_code_plan_str_representation PASSED  [ 77%]
tests/test_planning_engine.py::test_parse_plan_response PASSED           [ 77%]
tests/test_planning_engine.py::test_parse_plan_response_with_markdown PASSED [ 77%]
tests/test_planning_engine.py::test_generate_mock_plan_add_feature PASSED [ 77%]
tests/test_planning_engine.py::test_generate_mock_plan_fix_bug PASSED    [ 78%]
tests/test_planning_engine.py::test_fallback_plan_creation PASSED        [ 78%]
tests/test_planning_engine.py::test_format_file_tree PASSED              [ 78%]
tests/test_planning_engine_enhanced.py::test_code_plan_with_dependencies PASSED [ 78%]
tests/test_planning_engine_enhanced.py::test_code_plan_without_dependencies PASSED [ 79%]
tests/test_planning_engine_enhanced.py::test_code_plan_with_estimated_lines PASSED [ 79%]
tests/test_planning_engine_enhanced.py::test_generate_plan_with_file_tree_context PASSED [ 79%]
tests/test_planning_engine_enhanced.py::test_generate_plan_with_recent_changes_context PASSED [ 79%]
tests/test_planning_engine_enhanced.py::test_generate_plan_with_language_context PASSED [ 80%]
tests/test_planning_engine_enhanced.py::test_generate_plan_with_deployment_credentials PASSED [ 80%]
tests/test_planning_engine_enhanced.py::test_generate_plan_api_error_fallback PASSED [ 80%]
tests/test_planning_engine_enhanced.py::test_format_file_tree_with_list PASSED [ 80%]
tests/test_planning_engine_enhanced.py::test_format_file_tree_with_large_list PASSED [ 81%]
tests/test_planning_engine_enhanced.py::test_format_file_tree_with_string PASSED [ 81%]
tests/test_planning_engine_enhanced.py::test_parse_plan_response_clean_json PASSED [ 81%]
tests/test_planning_engine_enhanced.py::test_parse_plan_response_with_markdown_json PASSED [ 81%]
tests/test_planning_engine_enhanced.py::test_parse_plan_response_with_markdown PASSED [ 82%]
tests/test_planning_engine_enhanced.py::test_parse_plan_response_invalid_json PASSED [ 82%]
tests/test_planning_engine_enhanced.py::test_parse_plan_response_json_with_text PASSED [ 82%]
tests/test_planning_engine_enhanced.py::test_parse_plan_response_malformed_json_fallback PASSED [ 82%]
tests/test_planning_engine_enhanced.py::test_generate_mock_plan_add_feature PASSED [ 83%]
tests/test_planning_engine_enhanced.py::test_generate_mock_plan_add_test PASSED [ 83%]
tests/test_planning_engine_enhanced.py::test_generate_mock_plan_add_api PASSED [ 83%]
tests/test_planning_engine_enhanced.py::test_generate_mock_plan_add_cli PASSED [ 83%]
tests/test_planning_engine_enhanced.py::test_generate_mock_plan_fix_bug PASSED [ 84%]
tests/test_planning_engine_enhanced.py::test_generate_mock_plan_refactor PASSED [ 84%]
tests/test_planning_engine_enhanced.py::test_generate_mock_plan_improve PASSED [ 84%]
tests/test_planning_engine_enhanced.py::test_generate_mock_plan_generic PASSED [ 84%]
tests/test_planning_engine_enhanced.py::test_create_fallback_plan PASSED [ 85%]
tests/test_planning_engine_enhanced.py::test_generate_plan_with_all_context_types PASSED [ 85%]
tests/test_planning_engine_enhanced.py::test_generate_plan_empty_context PASSED [ 85%]
tests/test_planning_engine_enhanced.py::test_code_plan_to_dict_complete PASSED [ 85%]
tests/test_planning_engine_enhanced.py::test_generate_mock_plan_create_keyword PASSED [ 86%]
tests/test_planning_engine_enhanced.py::test_generate_mock_plan_implement_keyword PASSED [ 86%]
tests/test_promotion_gate.py::TestPromotionRules::test_default_rules PASSED [ 86%]
tests/test_promotion_gate.py::TestPromotionRules::test_custom_rules PASSED [ 86%]
tests/test_promotion_gate.py::TestPromotionDecision::test_decision_creation PASSED [ 87%]
tests/test_promotion_gate.py::TestPromotionDecision::test_add_reason PASSED [ 87%]
tests/test_promotion_gate.py::TestPromotionDecision::test_add_warning PASSED [ 87%]
tests/test_promotion_gate.py::TestPromotionGate::test_gate_initialization PASSED [ 88%]
tests/test_promotion_gate.py::TestPromotionGate::test_evaluate_nonexistent_workpad PASSED [ 88%]
tests/test_promotion_gate.py::TestPromotionGate::test_evaluate_without_tests_required PASSED [ 88%]
tests/test_promotion_gate.py::TestPromotionGate::test_evaluate_tests_required_but_not_run PASSED [ 88%]
tests/test_promotion_gate.py::TestPromotionGate::test_evaluate_tests_passed PASSED [ 89%]
tests/test_promotion_gate.py::TestPromotionGate::test_evaluate_tests_failed PASSED [ 89%]
tests/test_promotion_gate.py::TestPromotionGate::test_evaluate_fast_forward_possible PASSED [ 89%]
tests/test_promotion_gate.py::TestPromotionGate::test_evaluate_all_checks_pass PASSED [ 89%]
tests/test_promotion_gate.py::TestPromotionGate::test_format_decision PASSED [ 90%]
tests/test_promotion_gate.py::TestPromotionGate::test_format_reject_decision PASSED [ 90%]
tests/test_promotion_gate.py::TestPromotionGate::test_format_manual_review_decision PASSED [ 90%]
tests/test_promotion_gate.py::TestPromotionGateIntegration::test_full_workflow_approve PASSED [ 90%]
tests/test_promotion_gate.py::TestPromotionGateIntegration::test_full_workflow_reject PASSED [ 91%]
tests/test_test_analyzer.py::TestTestAnalyzer::test_analyzer_initialization PASSED [ 91%]
tests/test_test_analyzer.py::TestTestAnalyzer::test_analyze_passing_tests PASSED [ 91%]
tests/test_test_analyzer.py::TestTestAnalyzer::test_analyze_failing_tests PASSED [ 91%]
tests/test_test_analyzer.py::TestTestAnalyzer::test_identify_assertion_error PASSED [ 92%]
tests/test_test_analyzer.py::TestTestAnalyzer::test_identify_import_error PASSED [ 92%]
tests/test_test_analyzer.py::TestTestAnalyzer::test_identify_syntax_error PASSED [ 92%]
tests/test_test_analyzer.py::TestTestAnalyzer::test_identify_timeout PASSED [ 92%]
tests/test_test_analyzer.py::TestTestAnalyzer::test_suggested_actions_for_import_error PASSED [ 93%]
tests/test_test_analyzer.py::TestTestAnalyzer::test_suggested_actions_for_timeout PASSED [ 93%]
tests/test_test_analyzer.py::TestTestAnalyzer::test_complexity_estimation_low PASSED [ 93%]
tests/test_test_analyzer.py::TestTestAnalyzer::test_complexity_estimation_medium PASSED [ 93%]
tests/test_test_analyzer.py::TestTestAnalyzer::test_merge_similar_patterns PASSED [ 94%]
tests/test_test_analyzer.py::TestTestAnalyzer::test_format_analysis PASSED [ 94%]
tests/test_test_analyzer.py::TestTestAnalyzer::test_mixed_results PASSED [ 94%]
tests/test_test_analyzer.py::TestTestAnalyzer::test_extract_error_message PASSED [ 94%]
tests/test_test_analyzer.py::TestTestAnalyzer::test_extract_file_location PASSED [ 95%]
tests/test_test_analyzer.py::TestTestAnalyzer::test_categorize_network_error PASSED [ 95%]
tests/test_test_analyzer.py::TestTestAnalyzer::test_categorize_permission_error PASSED [ 95%]
tests/test_test_analyzer.py::TestTestAnalyzer::test_categorize_unknown_error PASSED [ 95%]
tests/test_workflow_e2e.py::test_complete_workflow PASSED                [ 96%]
tests/test_workflow_e2e.py::test_multiple_checkpoints PASSED             [ 96%]
tests/test_workflow_e2e.py::test_cannot_promote_diverged_trunk PASSED    [ 96%]
tests/test_workflow_e2e.py::test_get_repo_map PASSED                     [ 96%]
tests/test_workflow_e2e.py::test_revert_last_commit PASSED               [ 97%]
tests/test_workflow_e2e.py::test_patch_validation_conflict PASSED        [ 97%]
tests/test_workflow_e2e.py::test_init_from_git_url PASSED                [ 97%]
tests/test_workpad_enhancements.py::test_switch_workpad PASSED           [ 97%]
tests/test_workpad_enhancements.py::test_get_active_workpad_on_trunk PASSED [ 98%]
tests/test_workpad_enhancements.py::test_list_workpads_filtered PASSED   [ 98%]
tests/test_workpad_enhancements.py::test_compare_workpads PASSED         [ 98%]
tests/test_workpad_enhancements.py::test_get_workpad_merge_preview PASSED [ 98%]
tests/test_workpad_enhancements.py::test_get_workpad_merge_preview_diverged PASSED [ 99%]
tests/test_workpad_enhancements.py::test_cleanup_workpads_with_filters PASSED [ 99%]
tests/test_workpad_enhancements.py::test_switch_workpad_updates_activity PASSED [ 99%]
tests/test_workpad_enhancements.py::test_cleanup_workpads_repo_specific PASSED [100%]

==================================== ERRORS ====================================
_____ ERROR at setup of TestAutoMergeWorkflow.test_workflow_initialization _____
/opt/computersetup/.pyenv/versions/3.11.6/lib/python3.11/site-packages/urllib3/connectionpool.py:787: in urlopen
    response = self._make_request(
/opt/computersetup/.pyenv/versions/3.11.6/lib/python3.11/site-packages/urllib3/connectionpool.py:493: in _make_request
    conn.request(
/opt/computersetup/.pyenv/versions/3.11.6/lib/python3.11/site-packages/urllib3/connection.py:494: in request
    self.endheaders()
/opt/computersetup/.pyenv/versions/3.11.6/lib/python3.11/http/client.py:1281: in endheaders
    self._send_output(message_body, encode_chunked=encode_chunked)
/opt/computersetup/.pyenv/versions/3.11.6/lib/python3.11/http/client.py:1041: in _send_output
    self.send(msg)
/opt/computersetup/.pyenv/versions/3.11.6/lib/python3.11/http/client.py:979: in send
    self.connect()
../../.local/lib/python3.11/site-packages/docker/transport/unixconn.py:26: in connect
    sock.connect(self.unix_socket)
E   FileNotFoundError: [Errno 2] No such file or directory

During handling of the above exception, another exception occurred:
/opt/computersetup/.pyenv/versions/3.11.6/lib/python3.11/site-packages/requests/adapters.py:667: in send
    resp = conn.urlopen(
/opt/computersetup/.pyenv/versions/3.11.6/lib/python3.11/site-packages/urllib3/connectionpool.py:841: in urlopen
    retries = retries.increment(
/opt/computersetup/.pyenv/versions/3.11.6/lib/python3.11/site-packages/urllib3/util/retry.py:474: in increment
    raise reraise(type(error), error, _stacktrace)
          ^^^^^^^^^^^^^^^^^^^^^^^^^^^^^^^^^^^^^^^^
/opt/computersetup/.pyenv/versions/3.11.6/lib/python3.11/site-packages/urllib3/util/util.py:38: in reraise
    raise value.with_traceback(tb)
/opt/computersetup/.pyenv/versions/3.11.6/lib/python3.11/site-packages/urllib3/connectionpool.py:787: in urlopen
    response = self._make_request(
/opt/computersetup/.pyenv/versions/3.11.6/lib/python3.11/site-packages/urllib3/connectionpool.py:493: in _make_request
    conn.request(
/opt/computersetup/.pyenv/versions/3.11.6/lib/python3.11/site-packages/urllib3/connection.py:494: in request
    self.endheaders()
/opt/computersetup/.pyenv/versions/3.11.6/lib/python3.11/http/client.py:1281: in endheaders
    self._send_output(message_body, encode_chunked=encode_chunked)
/opt/computersetup/.pyenv/versions/3.11.6/lib/python3.11/http/client.py:1041: in _send_output
    self.send(msg)
/opt/computersetup/.pyenv/versions/3.11.6/lib/python3.11/http/client.py:979: in send
    self.connect()
../../.local/lib/python3.11/site-packages/docker/transport/unixconn.py:26: in connect
    sock.connect(self.unix_socket)
E   urllib3.exceptions.ProtocolError: ('Connection aborted.', FileNotFoundError(2, 'No such file or directory'))

During handling of the above exception, another exception occurred:
../../.local/lib/python3.11/site-packages/docker/api/client.py:223: in _retrieve_server_version
    return self.version(api_version=False)["ApiVersion"]
           ^^^^^^^^^^^^^^^^^^^^^^^^^^^^^^^
../../.local/lib/python3.11/site-packages/docker/api/daemon.py:181: in version
    return self._result(self._get(url), json=True)
                        ^^^^^^^^^^^^^^
../../.local/lib/python3.11/site-packages/docker/utils/decorators.py:44: in inner
    return f(self, *args, **kwargs)
           ^^^^^^^^^^^^^^^^^^^^^^^^
../../.local/lib/python3.11/site-packages/docker/api/client.py:246: in _get
    return self.get(url, **self._set_request_timeout(kwargs))
           ^^^^^^^^^^^^^^^^^^^^^^^^^^^^^^^^^^^^^^^^^^^^^^^^^^
/opt/computersetup/.pyenv/versions/3.11.6/lib/python3.11/site-packages/requests/sessions.py:602: in get
    return self.request("GET", url, **kwargs)
           ^^^^^^^^^^^^^^^^^^^^^^^^^^^^^^^^^^
/opt/computersetup/.pyenv/versions/3.11.6/lib/python3.11/site-packages/requests/sessions.py:589: in request
    resp = self.send(prep, **send_kwargs)
           ^^^^^^^^^^^^^^^^^^^^^^^^^^^^^^
/opt/computersetup/.pyenv/versions/3.11.6/lib/python3.11/site-packages/requests/sessions.py:703: in send
    r = adapter.send(request, **kwargs)
        ^^^^^^^^^^^^^^^^^^^^^^^^^^^^^^^
/opt/computersetup/.pyenv/versions/3.11.6/lib/python3.11/site-packages/requests/adapters.py:682: in send
    raise ConnectionError(err, request=request)
E   requests.exceptions.ConnectionError: ('Connection aborted.', FileNotFoundError(2, 'No such file or directory'))

The above exception was the direct cause of the following exception:
sologit/engines/test_orchestrator.py:86: in __init__
    self.docker_client = docker.from_env()
                         ^^^^^^^^^^^^^^^^^
../../.local/lib/python3.11/site-packages/docker/client.py:94: in from_env
    return cls(
../../.local/lib/python3.11/site-packages/docker/client.py:45: in __init__
    self.api = APIClient(*args, **kwargs)
               ^^^^^^^^^^^^^^^^^^^^^^^^^^
../../.local/lib/python3.11/site-packages/docker/api/client.py:207: in __init__
    self._version = self._retrieve_server_version()
                    ^^^^^^^^^^^^^^^^^^^^^^^^^^^^^^^
../../.local/lib/python3.11/site-packages/docker/api/client.py:230: in _retrieve_server_version
    raise DockerException(
E   docker.errors.DockerException: Error while fetching server API version: ('Connection aborted.', FileNotFoundError(2, 'No such file or directory'))

During handling of the above exception, another exception occurred:
tests/test_phase3_workflows.py:35: in test_orchestrator
    return TestOrchestrator(git_engine)
           ^^^^^^^^^^^^^^^^^^^^^^^^^^^^
sologit/engines/test_orchestrator.py:90: in __init__
    raise TestOrchestratorError(f"Docker not available: {e}")
E   sologit.engines.test_orchestrator.TestOrchestratorError: Docker not available: Error while fetching server API version: ('Connection aborted.', FileNotFoundError(2, 'No such file or directory'))
------------------------------ Captured log setup ------------------------------
ERROR    sologit.engines.test_orchestrator:test_orchestrator.py:89 Failed to connect to Docker: Error while fetching server API version: ('Connection aborted.', FileNotFoundError(2, 'No such file or directory'))
___ ERROR at setup of TestAutoMergeWorkflow.test_workflow_with_custom_rules ____
/opt/computersetup/.pyenv/versions/3.11.6/lib/python3.11/site-packages/urllib3/connectionpool.py:787: in urlopen
    response = self._make_request(
/opt/computersetup/.pyenv/versions/3.11.6/lib/python3.11/site-packages/urllib3/connectionpool.py:493: in _make_request
    conn.request(
/opt/computersetup/.pyenv/versions/3.11.6/lib/python3.11/site-packages/urllib3/connection.py:494: in request
    self.endheaders()
/opt/computersetup/.pyenv/versions/3.11.6/lib/python3.11/http/client.py:1281: in endheaders
    self._send_output(message_body, encode_chunked=encode_chunked)
/opt/computersetup/.pyenv/versions/3.11.6/lib/python3.11/http/client.py:1041: in _send_output
    self.send(msg)
/opt/computersetup/.pyenv/versions/3.11.6/lib/python3.11/http/client.py:979: in send
    self.connect()
../../.local/lib/python3.11/site-packages/docker/transport/unixconn.py:26: in connect
    sock.connect(self.unix_socket)
E   FileNotFoundError: [Errno 2] No such file or directory

During handling of the above exception, another exception occurred:
/opt/computersetup/.pyenv/versions/3.11.6/lib/python3.11/site-packages/requests/adapters.py:667: in send
    resp = conn.urlopen(
/opt/computersetup/.pyenv/versions/3.11.6/lib/python3.11/site-packages/urllib3/connectionpool.py:841: in urlopen
    retries = retries.increment(
/opt/computersetup/.pyenv/versions/3.11.6/lib/python3.11/site-packages/urllib3/util/retry.py:474: in increment
    raise reraise(type(error), error, _stacktrace)
          ^^^^^^^^^^^^^^^^^^^^^^^^^^^^^^^^^^^^^^^^
/opt/computersetup/.pyenv/versions/3.11.6/lib/python3.11/site-packages/urllib3/util/util.py:38: in reraise
    raise value.with_traceback(tb)
/opt/computersetup/.pyenv/versions/3.11.6/lib/python3.11/site-packages/urllib3/connectionpool.py:787: in urlopen
    response = self._make_request(
/opt/computersetup/.pyenv/versions/3.11.6/lib/python3.11/site-packages/urllib3/connectionpool.py:493: in _make_request
    conn.request(
/opt/computersetup/.pyenv/versions/3.11.6/lib/python3.11/site-packages/urllib3/connection.py:494: in request
    self.endheaders()
/opt/computersetup/.pyenv/versions/3.11.6/lib/python3.11/http/client.py:1281: in endheaders
    self._send_output(message_body, encode_chunked=encode_chunked)
/opt/computersetup/.pyenv/versions/3.11.6/lib/python3.11/http/client.py:1041: in _send_output
    self.send(msg)
/opt/computersetup/.pyenv/versions/3.11.6/lib/python3.11/http/client.py:979: in send
    self.connect()
../../.local/lib/python3.11/site-packages/docker/transport/unixconn.py:26: in connect
    sock.connect(self.unix_socket)
E   urllib3.exceptions.ProtocolError: ('Connection aborted.', FileNotFoundError(2, 'No such file or directory'))

During handling of the above exception, another exception occurred:
../../.local/lib/python3.11/site-packages/docker/api/client.py:223: in _retrieve_server_version
    return self.version(api_version=False)["ApiVersion"]
           ^^^^^^^^^^^^^^^^^^^^^^^^^^^^^^^
../../.local/lib/python3.11/site-packages/docker/api/daemon.py:181: in version
    return self._result(self._get(url), json=True)
                        ^^^^^^^^^^^^^^
../../.local/lib/python3.11/site-packages/docker/utils/decorators.py:44: in inner
    return f(self, *args, **kwargs)
           ^^^^^^^^^^^^^^^^^^^^^^^^
../../.local/lib/python3.11/site-packages/docker/api/client.py:246: in _get
    return self.get(url, **self._set_request_timeout(kwargs))
           ^^^^^^^^^^^^^^^^^^^^^^^^^^^^^^^^^^^^^^^^^^^^^^^^^^
/opt/computersetup/.pyenv/versions/3.11.6/lib/python3.11/site-packages/requests/sessions.py:602: in get
    return self.request("GET", url, **kwargs)
           ^^^^^^^^^^^^^^^^^^^^^^^^^^^^^^^^^^
/opt/computersetup/.pyenv/versions/3.11.6/lib/python3.11/site-packages/requests/sessions.py:589: in request
    resp = self.send(prep, **send_kwargs)
           ^^^^^^^^^^^^^^^^^^^^^^^^^^^^^^
/opt/computersetup/.pyenv/versions/3.11.6/lib/python3.11/site-packages/requests/sessions.py:703: in send
    r = adapter.send(request, **kwargs)
        ^^^^^^^^^^^^^^^^^^^^^^^^^^^^^^^
/opt/computersetup/.pyenv/versions/3.11.6/lib/python3.11/site-packages/requests/adapters.py:682: in send
    raise ConnectionError(err, request=request)
E   requests.exceptions.ConnectionError: ('Connection aborted.', FileNotFoundError(2, 'No such file or directory'))

The above exception was the direct cause of the following exception:
sologit/engines/test_orchestrator.py:86: in __init__
    self.docker_client = docker.from_env()
                         ^^^^^^^^^^^^^^^^^
../../.local/lib/python3.11/site-packages/docker/client.py:94: in from_env
    return cls(
../../.local/lib/python3.11/site-packages/docker/client.py:45: in __init__
    self.api = APIClient(*args, **kwargs)
               ^^^^^^^^^^^^^^^^^^^^^^^^^^
../../.local/lib/python3.11/site-packages/docker/api/client.py:207: in __init__
    self._version = self._retrieve_server_version()
                    ^^^^^^^^^^^^^^^^^^^^^^^^^^^^^^^
../../.local/lib/python3.11/site-packages/docker/api/client.py:230: in _retrieve_server_version
    raise DockerException(
E   docker.errors.DockerException: Error while fetching server API version: ('Connection aborted.', FileNotFoundError(2, 'No such file or directory'))

During handling of the above exception, another exception occurred:
tests/test_phase3_workflows.py:35: in test_orchestrator
    return TestOrchestrator(git_engine)
           ^^^^^^^^^^^^^^^^^^^^^^^^^^^^
sologit/engines/test_orchestrator.py:90: in __init__
    raise TestOrchestratorError(f"Docker not available: {e}")
E   sologit.engines.test_orchestrator.TestOrchestratorError: Docker not available: Error while fetching server API version: ('Connection aborted.', FileNotFoundError(2, 'No such file or directory'))
------------------------------ Captured log setup ------------------------------
ERROR    sologit.engines.test_orchestrator:test_orchestrator.py:89 Failed to connect to Docker: Error while fetching server API version: ('Connection aborted.', FileNotFoundError(2, 'No such file or directory'))
___ ERROR at setup of TestAutoMergeWorkflow.test_execute_nonexistent_workpad ___
/opt/computersetup/.pyenv/versions/3.11.6/lib/python3.11/site-packages/urllib3/connectionpool.py:787: in urlopen
    response = self._make_request(
/opt/computersetup/.pyenv/versions/3.11.6/lib/python3.11/site-packages/urllib3/connectionpool.py:493: in _make_request
    conn.request(
/opt/computersetup/.pyenv/versions/3.11.6/lib/python3.11/site-packages/urllib3/connection.py:494: in request
    self.endheaders()
/opt/computersetup/.pyenv/versions/3.11.6/lib/python3.11/http/client.py:1281: in endheaders
    self._send_output(message_body, encode_chunked=encode_chunked)
/opt/computersetup/.pyenv/versions/3.11.6/lib/python3.11/http/client.py:1041: in _send_output
    self.send(msg)
/opt/computersetup/.pyenv/versions/3.11.6/lib/python3.11/http/client.py:979: in send
    self.connect()
../../.local/lib/python3.11/site-packages/docker/transport/unixconn.py:26: in connect
    sock.connect(self.unix_socket)
E   FileNotFoundError: [Errno 2] No such file or directory

During handling of the above exception, another exception occurred:
/opt/computersetup/.pyenv/versions/3.11.6/lib/python3.11/site-packages/requests/adapters.py:667: in send
    resp = conn.urlopen(
/opt/computersetup/.pyenv/versions/3.11.6/lib/python3.11/site-packages/urllib3/connectionpool.py:841: in urlopen
    retries = retries.increment(
/opt/computersetup/.pyenv/versions/3.11.6/lib/python3.11/site-packages/urllib3/util/retry.py:474: in increment
    raise reraise(type(error), error, _stacktrace)
          ^^^^^^^^^^^^^^^^^^^^^^^^^^^^^^^^^^^^^^^^
/opt/computersetup/.pyenv/versions/3.11.6/lib/python3.11/site-packages/urllib3/util/util.py:38: in reraise
    raise value.with_traceback(tb)
/opt/computersetup/.pyenv/versions/3.11.6/lib/python3.11/site-packages/urllib3/connectionpool.py:787: in urlopen
    response = self._make_request(
/opt/computersetup/.pyenv/versions/3.11.6/lib/python3.11/site-packages/urllib3/connectionpool.py:493: in _make_request
    conn.request(
/opt/computersetup/.pyenv/versions/3.11.6/lib/python3.11/site-packages/urllib3/connection.py:494: in request
    self.endheaders()
/opt/computersetup/.pyenv/versions/3.11.6/lib/python3.11/http/client.py:1281: in endheaders
    self._send_output(message_body, encode_chunked=encode_chunked)
/opt/computersetup/.pyenv/versions/3.11.6/lib/python3.11/http/client.py:1041: in _send_output
    self.send(msg)
/opt/computersetup/.pyenv/versions/3.11.6/lib/python3.11/http/client.py:979: in send
    self.connect()
../../.local/lib/python3.11/site-packages/docker/transport/unixconn.py:26: in connect
    sock.connect(self.unix_socket)
E   urllib3.exceptions.ProtocolError: ('Connection aborted.', FileNotFoundError(2, 'No such file or directory'))

During handling of the above exception, another exception occurred:
../../.local/lib/python3.11/site-packages/docker/api/client.py:223: in _retrieve_server_version
    return self.version(api_version=False)["ApiVersion"]
           ^^^^^^^^^^^^^^^^^^^^^^^^^^^^^^^
../../.local/lib/python3.11/site-packages/docker/api/daemon.py:181: in version
    return self._result(self._get(url), json=True)
                        ^^^^^^^^^^^^^^
../../.local/lib/python3.11/site-packages/docker/utils/decorators.py:44: in inner
    return f(self, *args, **kwargs)
           ^^^^^^^^^^^^^^^^^^^^^^^^
../../.local/lib/python3.11/site-packages/docker/api/client.py:246: in _get
    return self.get(url, **self._set_request_timeout(kwargs))
           ^^^^^^^^^^^^^^^^^^^^^^^^^^^^^^^^^^^^^^^^^^^^^^^^^^
/opt/computersetup/.pyenv/versions/3.11.6/lib/python3.11/site-packages/requests/sessions.py:602: in get
    return self.request("GET", url, **kwargs)
           ^^^^^^^^^^^^^^^^^^^^^^^^^^^^^^^^^^
/opt/computersetup/.pyenv/versions/3.11.6/lib/python3.11/site-packages/requests/sessions.py:589: in request
    resp = self.send(prep, **send_kwargs)
           ^^^^^^^^^^^^^^^^^^^^^^^^^^^^^^
/opt/computersetup/.pyenv/versions/3.11.6/lib/python3.11/site-packages/requests/sessions.py:703: in send
    r = adapter.send(request, **kwargs)
        ^^^^^^^^^^^^^^^^^^^^^^^^^^^^^^^
/opt/computersetup/.pyenv/versions/3.11.6/lib/python3.11/site-packages/requests/adapters.py:682: in send
    raise ConnectionError(err, request=request)
E   requests.exceptions.ConnectionError: ('Connection aborted.', FileNotFoundError(2, 'No such file or directory'))

The above exception was the direct cause of the following exception:
sologit/engines/test_orchestrator.py:86: in __init__
    self.docker_client = docker.from_env()
                         ^^^^^^^^^^^^^^^^^
../../.local/lib/python3.11/site-packages/docker/client.py:94: in from_env
    return cls(
../../.local/lib/python3.11/site-packages/docker/client.py:45: in __init__
    self.api = APIClient(*args, **kwargs)
               ^^^^^^^^^^^^^^^^^^^^^^^^^^
../../.local/lib/python3.11/site-packages/docker/api/client.py:207: in __init__
    self._version = self._retrieve_server_version()
                    ^^^^^^^^^^^^^^^^^^^^^^^^^^^^^^^
../../.local/lib/python3.11/site-packages/docker/api/client.py:230: in _retrieve_server_version
    raise DockerException(
E   docker.errors.DockerException: Error while fetching server API version: ('Connection aborted.', FileNotFoundError(2, 'No such file or directory'))

During handling of the above exception, another exception occurred:
tests/test_phase3_workflows.py:35: in test_orchestrator
    return TestOrchestrator(git_engine)
           ^^^^^^^^^^^^^^^^^^^^^^^^^^^^
sologit/engines/test_orchestrator.py:90: in __init__
    raise TestOrchestratorError(f"Docker not available: {e}")
E   sologit.engines.test_orchestrator.TestOrchestratorError: Docker not available: Error while fetching server API version: ('Connection aborted.', FileNotFoundError(2, 'No such file or directory'))
------------------------------ Captured log setup ------------------------------
ERROR    sologit.engines.test_orchestrator:test_orchestrator.py:89 Failed to connect to Docker: Error while fetching server API version: ('Connection aborted.', FileNotFoundError(2, 'No such file or directory'))
__________ ERROR at setup of TestAutoMergeWorkflow.test_format_result __________
/opt/computersetup/.pyenv/versions/3.11.6/lib/python3.11/site-packages/urllib3/connectionpool.py:787: in urlopen
    response = self._make_request(
/opt/computersetup/.pyenv/versions/3.11.6/lib/python3.11/site-packages/urllib3/connectionpool.py:493: in _make_request
    conn.request(
/opt/computersetup/.pyenv/versions/3.11.6/lib/python3.11/site-packages/urllib3/connection.py:494: in request
    self.endheaders()
/opt/computersetup/.pyenv/versions/3.11.6/lib/python3.11/http/client.py:1281: in endheaders
    self._send_output(message_body, encode_chunked=encode_chunked)
/opt/computersetup/.pyenv/versions/3.11.6/lib/python3.11/http/client.py:1041: in _send_output
    self.send(msg)
/opt/computersetup/.pyenv/versions/3.11.6/lib/python3.11/http/client.py:979: in send
    self.connect()
../../.local/lib/python3.11/site-packages/docker/transport/unixconn.py:26: in connect
    sock.connect(self.unix_socket)
E   FileNotFoundError: [Errno 2] No such file or directory

During handling of the above exception, another exception occurred:
/opt/computersetup/.pyenv/versions/3.11.6/lib/python3.11/site-packages/requests/adapters.py:667: in send
    resp = conn.urlopen(
/opt/computersetup/.pyenv/versions/3.11.6/lib/python3.11/site-packages/urllib3/connectionpool.py:841: in urlopen
    retries = retries.increment(
/opt/computersetup/.pyenv/versions/3.11.6/lib/python3.11/site-packages/urllib3/util/retry.py:474: in increment
    raise reraise(type(error), error, _stacktrace)
          ^^^^^^^^^^^^^^^^^^^^^^^^^^^^^^^^^^^^^^^^
/opt/computersetup/.pyenv/versions/3.11.6/lib/python3.11/site-packages/urllib3/util/util.py:38: in reraise
    raise value.with_traceback(tb)
/opt/computersetup/.pyenv/versions/3.11.6/lib/python3.11/site-packages/urllib3/connectionpool.py:787: in urlopen
    response = self._make_request(
/opt/computersetup/.pyenv/versions/3.11.6/lib/python3.11/site-packages/urllib3/connectionpool.py:493: in _make_request
    conn.request(
/opt/computersetup/.pyenv/versions/3.11.6/lib/python3.11/site-packages/urllib3/connection.py:494: in request
    self.endheaders()
/opt/computersetup/.pyenv/versions/3.11.6/lib/python3.11/http/client.py:1281: in endheaders
    self._send_output(message_body, encode_chunked=encode_chunked)
/opt/computersetup/.pyenv/versions/3.11.6/lib/python3.11/http/client.py:1041: in _send_output
    self.send(msg)
/opt/computersetup/.pyenv/versions/3.11.6/lib/python3.11/http/client.py:979: in send
    self.connect()
../../.local/lib/python3.11/site-packages/docker/transport/unixconn.py:26: in connect
    sock.connect(self.unix_socket)
E   urllib3.exceptions.ProtocolError: ('Connection aborted.', FileNotFoundError(2, 'No such file or directory'))

During handling of the above exception, another exception occurred:
../../.local/lib/python3.11/site-packages/docker/api/client.py:223: in _retrieve_server_version
    return self.version(api_version=False)["ApiVersion"]
           ^^^^^^^^^^^^^^^^^^^^^^^^^^^^^^^
../../.local/lib/python3.11/site-packages/docker/api/daemon.py:181: in version
    return self._result(self._get(url), json=True)
                        ^^^^^^^^^^^^^^
../../.local/lib/python3.11/site-packages/docker/utils/decorators.py:44: in inner
    return f(self, *args, **kwargs)
           ^^^^^^^^^^^^^^^^^^^^^^^^
../../.local/lib/python3.11/site-packages/docker/api/client.py:246: in _get
    return self.get(url, **self._set_request_timeout(kwargs))
           ^^^^^^^^^^^^^^^^^^^^^^^^^^^^^^^^^^^^^^^^^^^^^^^^^^
/opt/computersetup/.pyenv/versions/3.11.6/lib/python3.11/site-packages/requests/sessions.py:602: in get
    return self.request("GET", url, **kwargs)
           ^^^^^^^^^^^^^^^^^^^^^^^^^^^^^^^^^^
/opt/computersetup/.pyenv/versions/3.11.6/lib/python3.11/site-packages/requests/sessions.py:589: in request
    resp = self.send(prep, **send_kwargs)
           ^^^^^^^^^^^^^^^^^^^^^^^^^^^^^^
/opt/computersetup/.pyenv/versions/3.11.6/lib/python3.11/site-packages/requests/sessions.py:703: in send
    r = adapter.send(request, **kwargs)
        ^^^^^^^^^^^^^^^^^^^^^^^^^^^^^^^
/opt/computersetup/.pyenv/versions/3.11.6/lib/python3.11/site-packages/requests/adapters.py:682: in send
    raise ConnectionError(err, request=request)
E   requests.exceptions.ConnectionError: ('Connection aborted.', FileNotFoundError(2, 'No such file or directory'))

The above exception was the direct cause of the following exception:
sologit/engines/test_orchestrator.py:86: in __init__
    self.docker_client = docker.from_env()
                         ^^^^^^^^^^^^^^^^^
../../.local/lib/python3.11/site-packages/docker/client.py:94: in from_env
    return cls(
../../.local/lib/python3.11/site-packages/docker/client.py:45: in __init__
    self.api = APIClient(*args, **kwargs)
               ^^^^^^^^^^^^^^^^^^^^^^^^^^
../../.local/lib/python3.11/site-packages/docker/api/client.py:207: in __init__
    self._version = self._retrieve_server_version()
                    ^^^^^^^^^^^^^^^^^^^^^^^^^^^^^^^
../../.local/lib/python3.11/site-packages/docker/api/client.py:230: in _retrieve_server_version
    raise DockerException(
E   docker.errors.DockerException: Error while fetching server API version: ('Connection aborted.', FileNotFoundError(2, 'No such file or directory'))

During handling of the above exception, another exception occurred:
tests/test_phase3_workflows.py:35: in test_orchestrator
    return TestOrchestrator(git_engine)
           ^^^^^^^^^^^^^^^^^^^^^^^^^^^^
sologit/engines/test_orchestrator.py:90: in __init__
    raise TestOrchestratorError(f"Docker not available: {e}")
E   sologit.engines.test_orchestrator.TestOrchestratorError: Docker not available: Error while fetching server API version: ('Connection aborted.', FileNotFoundError(2, 'No such file or directory'))
------------------------------ Captured log setup ------------------------------
ERROR    sologit.engines.test_orchestrator:test_orchestrator.py:89 Failed to connect to Docker: Error while fetching server API version: ('Connection aborted.', FileNotFoundError(2, 'No such file or directory'))
____ ERROR at setup of TestCIOrchestrator.test_orchestrator_initialization _____
/opt/computersetup/.pyenv/versions/3.11.6/lib/python3.11/site-packages/urllib3/connectionpool.py:787: in urlopen
    response = self._make_request(
/opt/computersetup/.pyenv/versions/3.11.6/lib/python3.11/site-packages/urllib3/connectionpool.py:493: in _make_request
    conn.request(
/opt/computersetup/.pyenv/versions/3.11.6/lib/python3.11/site-packages/urllib3/connection.py:494: in request
    self.endheaders()
/opt/computersetup/.pyenv/versions/3.11.6/lib/python3.11/http/client.py:1281: in endheaders
    self._send_output(message_body, encode_chunked=encode_chunked)
/opt/computersetup/.pyenv/versions/3.11.6/lib/python3.11/http/client.py:1041: in _send_output
    self.send(msg)
/opt/computersetup/.pyenv/versions/3.11.6/lib/python3.11/http/client.py:979: in send
    self.connect()
../../.local/lib/python3.11/site-packages/docker/transport/unixconn.py:26: in connect
    sock.connect(self.unix_socket)
E   FileNotFoundError: [Errno 2] No such file or directory

During handling of the above exception, another exception occurred:
/opt/computersetup/.pyenv/versions/3.11.6/lib/python3.11/site-packages/requests/adapters.py:667: in send
    resp = conn.urlopen(
/opt/computersetup/.pyenv/versions/3.11.6/lib/python3.11/site-packages/urllib3/connectionpool.py:841: in urlopen
    retries = retries.increment(
/opt/computersetup/.pyenv/versions/3.11.6/lib/python3.11/site-packages/urllib3/util/retry.py:474: in increment
    raise reraise(type(error), error, _stacktrace)
          ^^^^^^^^^^^^^^^^^^^^^^^^^^^^^^^^^^^^^^^^
/opt/computersetup/.pyenv/versions/3.11.6/lib/python3.11/site-packages/urllib3/util/util.py:38: in reraise
    raise value.with_traceback(tb)
/opt/computersetup/.pyenv/versions/3.11.6/lib/python3.11/site-packages/urllib3/connectionpool.py:787: in urlopen
    response = self._make_request(
/opt/computersetup/.pyenv/versions/3.11.6/lib/python3.11/site-packages/urllib3/connectionpool.py:493: in _make_request
    conn.request(
/opt/computersetup/.pyenv/versions/3.11.6/lib/python3.11/site-packages/urllib3/connection.py:494: in request
    self.endheaders()
/opt/computersetup/.pyenv/versions/3.11.6/lib/python3.11/http/client.py:1281: in endheaders
    self._send_output(message_body, encode_chunked=encode_chunked)
/opt/computersetup/.pyenv/versions/3.11.6/lib/python3.11/http/client.py:1041: in _send_output
    self.send(msg)
/opt/computersetup/.pyenv/versions/3.11.6/lib/python3.11/http/client.py:979: in send
    self.connect()
../../.local/lib/python3.11/site-packages/docker/transport/unixconn.py:26: in connect
    sock.connect(self.unix_socket)
E   urllib3.exceptions.ProtocolError: ('Connection aborted.', FileNotFoundError(2, 'No such file or directory'))

During handling of the above exception, another exception occurred:
../../.local/lib/python3.11/site-packages/docker/api/client.py:223: in _retrieve_server_version
    return self.version(api_version=False)["ApiVersion"]
           ^^^^^^^^^^^^^^^^^^^^^^^^^^^^^^^
../../.local/lib/python3.11/site-packages/docker/api/daemon.py:181: in version
    return self._result(self._get(url), json=True)
                        ^^^^^^^^^^^^^^
../../.local/lib/python3.11/site-packages/docker/utils/decorators.py:44: in inner
    return f(self, *args, **kwargs)
           ^^^^^^^^^^^^^^^^^^^^^^^^
../../.local/lib/python3.11/site-packages/docker/api/client.py:246: in _get
    return self.get(url, **self._set_request_timeout(kwargs))
           ^^^^^^^^^^^^^^^^^^^^^^^^^^^^^^^^^^^^^^^^^^^^^^^^^^
/opt/computersetup/.pyenv/versions/3.11.6/lib/python3.11/site-packages/requests/sessions.py:602: in get
    return self.request("GET", url, **kwargs)
           ^^^^^^^^^^^^^^^^^^^^^^^^^^^^^^^^^^
/opt/computersetup/.pyenv/versions/3.11.6/lib/python3.11/site-packages/requests/sessions.py:589: in request
    resp = self.send(prep, **send_kwargs)
           ^^^^^^^^^^^^^^^^^^^^^^^^^^^^^^
/opt/computersetup/.pyenv/versions/3.11.6/lib/python3.11/site-packages/requests/sessions.py:703: in send
    r = adapter.send(request, **kwargs)
        ^^^^^^^^^^^^^^^^^^^^^^^^^^^^^^^
/opt/computersetup/.pyenv/versions/3.11.6/lib/python3.11/site-packages/requests/adapters.py:682: in send
    raise ConnectionError(err, request=request)
E   requests.exceptions.ConnectionError: ('Connection aborted.', FileNotFoundError(2, 'No such file or directory'))

The above exception was the direct cause of the following exception:
sologit/engines/test_orchestrator.py:86: in __init__
    self.docker_client = docker.from_env()
                         ^^^^^^^^^^^^^^^^^
../../.local/lib/python3.11/site-packages/docker/client.py:94: in from_env
    return cls(
../../.local/lib/python3.11/site-packages/docker/client.py:45: in __init__
    self.api = APIClient(*args, **kwargs)
               ^^^^^^^^^^^^^^^^^^^^^^^^^^
../../.local/lib/python3.11/site-packages/docker/api/client.py:207: in __init__
    self._version = self._retrieve_server_version()
                    ^^^^^^^^^^^^^^^^^^^^^^^^^^^^^^^
../../.local/lib/python3.11/site-packages/docker/api/client.py:230: in _retrieve_server_version
    raise DockerException(
E   docker.errors.DockerException: Error while fetching server API version: ('Connection aborted.', FileNotFoundError(2, 'No such file or directory'))

During handling of the above exception, another exception occurred:
tests/test_phase3_workflows.py:35: in test_orchestrator
    return TestOrchestrator(git_engine)
           ^^^^^^^^^^^^^^^^^^^^^^^^^^^^
sologit/engines/test_orchestrator.py:90: in __init__
    raise TestOrchestratorError(f"Docker not available: {e}")
E   sologit.engines.test_orchestrator.TestOrchestratorError: Docker not available: Error while fetching server API version: ('Connection aborted.', FileNotFoundError(2, 'No such file or directory'))
------------------------------ Captured log setup ------------------------------
ERROR    sologit.engines.test_orchestrator:test_orchestrator.py:89 Failed to connect to Docker: Error while fetching server API version: ('Connection aborted.', FileNotFoundError(2, 'No such file or directory'))
__ ERROR at setup of TestCIOrchestrator.test_run_smoke_tests_nonexistent_repo __
/opt/computersetup/.pyenv/versions/3.11.6/lib/python3.11/site-packages/urllib3/connectionpool.py:787: in urlopen
    response = self._make_request(
/opt/computersetup/.pyenv/versions/3.11.6/lib/python3.11/site-packages/urllib3/connectionpool.py:493: in _make_request
    conn.request(
/opt/computersetup/.pyenv/versions/3.11.6/lib/python3.11/site-packages/urllib3/connection.py:494: in request
    self.endheaders()
/opt/computersetup/.pyenv/versions/3.11.6/lib/python3.11/http/client.py:1281: in endheaders
    self._send_output(message_body, encode_chunked=encode_chunked)
/opt/computersetup/.pyenv/versions/3.11.6/lib/python3.11/http/client.py:1041: in _send_output
    self.send(msg)
/opt/computersetup/.pyenv/versions/3.11.6/lib/python3.11/http/client.py:979: in send
    self.connect()
../../.local/lib/python3.11/site-packages/docker/transport/unixconn.py:26: in connect
    sock.connect(self.unix_socket)
E   FileNotFoundError: [Errno 2] No such file or directory

During handling of the above exception, another exception occurred:
/opt/computersetup/.pyenv/versions/3.11.6/lib/python3.11/site-packages/requests/adapters.py:667: in send
    resp = conn.urlopen(
/opt/computersetup/.pyenv/versions/3.11.6/lib/python3.11/site-packages/urllib3/connectionpool.py:841: in urlopen
    retries = retries.increment(
/opt/computersetup/.pyenv/versions/3.11.6/lib/python3.11/site-packages/urllib3/util/retry.py:474: in increment
    raise reraise(type(error), error, _stacktrace)
          ^^^^^^^^^^^^^^^^^^^^^^^^^^^^^^^^^^^^^^^^
/opt/computersetup/.pyenv/versions/3.11.6/lib/python3.11/site-packages/urllib3/util/util.py:38: in reraise
    raise value.with_traceback(tb)
/opt/computersetup/.pyenv/versions/3.11.6/lib/python3.11/site-packages/urllib3/connectionpool.py:787: in urlopen
    response = self._make_request(
/opt/computersetup/.pyenv/versions/3.11.6/lib/python3.11/site-packages/urllib3/connectionpool.py:493: in _make_request
    conn.request(
/opt/computersetup/.pyenv/versions/3.11.6/lib/python3.11/site-packages/urllib3/connection.py:494: in request
    self.endheaders()
/opt/computersetup/.pyenv/versions/3.11.6/lib/python3.11/http/client.py:1281: in endheaders
    self._send_output(message_body, encode_chunked=encode_chunked)
/opt/computersetup/.pyenv/versions/3.11.6/lib/python3.11/http/client.py:1041: in _send_output
    self.send(msg)
/opt/computersetup/.pyenv/versions/3.11.6/lib/python3.11/http/client.py:979: in send
    self.connect()
../../.local/lib/python3.11/site-packages/docker/transport/unixconn.py:26: in connect
    sock.connect(self.unix_socket)
E   urllib3.exceptions.ProtocolError: ('Connection aborted.', FileNotFoundError(2, 'No such file or directory'))

During handling of the above exception, another exception occurred:
../../.local/lib/python3.11/site-packages/docker/api/client.py:223: in _retrieve_server_version
    return self.version(api_version=False)["ApiVersion"]
           ^^^^^^^^^^^^^^^^^^^^^^^^^^^^^^^
../../.local/lib/python3.11/site-packages/docker/api/daemon.py:181: in version
    return self._result(self._get(url), json=True)
                        ^^^^^^^^^^^^^^
../../.local/lib/python3.11/site-packages/docker/utils/decorators.py:44: in inner
    return f(self, *args, **kwargs)
           ^^^^^^^^^^^^^^^^^^^^^^^^
../../.local/lib/python3.11/site-packages/docker/api/client.py:246: in _get
    return self.get(url, **self._set_request_timeout(kwargs))
           ^^^^^^^^^^^^^^^^^^^^^^^^^^^^^^^^^^^^^^^^^^^^^^^^^^
/opt/computersetup/.pyenv/versions/3.11.6/lib/python3.11/site-packages/requests/sessions.py:602: in get
    return self.request("GET", url, **kwargs)
           ^^^^^^^^^^^^^^^^^^^^^^^^^^^^^^^^^^
/opt/computersetup/.pyenv/versions/3.11.6/lib/python3.11/site-packages/requests/sessions.py:589: in request
    resp = self.send(prep, **send_kwargs)
           ^^^^^^^^^^^^^^^^^^^^^^^^^^^^^^
/opt/computersetup/.pyenv/versions/3.11.6/lib/python3.11/site-packages/requests/sessions.py:703: in send
    r = adapter.send(request, **kwargs)
        ^^^^^^^^^^^^^^^^^^^^^^^^^^^^^^^
/opt/computersetup/.pyenv/versions/3.11.6/lib/python3.11/site-packages/requests/adapters.py:682: in send
    raise ConnectionError(err, request=request)
E   requests.exceptions.ConnectionError: ('Connection aborted.', FileNotFoundError(2, 'No such file or directory'))

The above exception was the direct cause of the following exception:
sologit/engines/test_orchestrator.py:86: in __init__
    self.docker_client = docker.from_env()
                         ^^^^^^^^^^^^^^^^^
../../.local/lib/python3.11/site-packages/docker/client.py:94: in from_env
    return cls(
../../.local/lib/python3.11/site-packages/docker/client.py:45: in __init__
    self.api = APIClient(*args, **kwargs)
               ^^^^^^^^^^^^^^^^^^^^^^^^^^
../../.local/lib/python3.11/site-packages/docker/api/client.py:207: in __init__
    self._version = self._retrieve_server_version()
                    ^^^^^^^^^^^^^^^^^^^^^^^^^^^^^^^
../../.local/lib/python3.11/site-packages/docker/api/client.py:230: in _retrieve_server_version
    raise DockerException(
E   docker.errors.DockerException: Error while fetching server API version: ('Connection aborted.', FileNotFoundError(2, 'No such file or directory'))

During handling of the above exception, another exception occurred:
tests/test_phase3_workflows.py:35: in test_orchestrator
    return TestOrchestrator(git_engine)
           ^^^^^^^^^^^^^^^^^^^^^^^^^^^^
sologit/engines/test_orchestrator.py:90: in __init__
    raise TestOrchestratorError(f"Docker not available: {e}")
E   sologit.engines.test_orchestrator.TestOrchestratorError: Docker not available: Error while fetching server API version: ('Connection aborted.', FileNotFoundError(2, 'No such file or directory'))
------------------------------ Captured log setup ------------------------------
ERROR    sologit.engines.test_orchestrator:test_orchestrator.py:89 Failed to connect to Docker: Error while fetching server API version: ('Connection aborted.', FileNotFoundError(2, 'No such file or directory'))
__________ ERROR at setup of TestCIOrchestrator.test_format_ci_result __________
/opt/computersetup/.pyenv/versions/3.11.6/lib/python3.11/site-packages/urllib3/connectionpool.py:787: in urlopen
    response = self._make_request(
/opt/computersetup/.pyenv/versions/3.11.6/lib/python3.11/site-packages/urllib3/connectionpool.py:493: in _make_request
    conn.request(
/opt/computersetup/.pyenv/versions/3.11.6/lib/python3.11/site-packages/urllib3/connection.py:494: in request
    self.endheaders()
/opt/computersetup/.pyenv/versions/3.11.6/lib/python3.11/http/client.py:1281: in endheaders
    self._send_output(message_body, encode_chunked=encode_chunked)
/opt/computersetup/.pyenv/versions/3.11.6/lib/python3.11/http/client.py:1041: in _send_output
    self.send(msg)
/opt/computersetup/.pyenv/versions/3.11.6/lib/python3.11/http/client.py:979: in send
    self.connect()
../../.local/lib/python3.11/site-packages/docker/transport/unixconn.py:26: in connect
    sock.connect(self.unix_socket)
E   FileNotFoundError: [Errno 2] No such file or directory

During handling of the above exception, another exception occurred:
/opt/computersetup/.pyenv/versions/3.11.6/lib/python3.11/site-packages/requests/adapters.py:667: in send
    resp = conn.urlopen(
/opt/computersetup/.pyenv/versions/3.11.6/lib/python3.11/site-packages/urllib3/connectionpool.py:841: in urlopen
    retries = retries.increment(
/opt/computersetup/.pyenv/versions/3.11.6/lib/python3.11/site-packages/urllib3/util/retry.py:474: in increment
    raise reraise(type(error), error, _stacktrace)
          ^^^^^^^^^^^^^^^^^^^^^^^^^^^^^^^^^^^^^^^^
/opt/computersetup/.pyenv/versions/3.11.6/lib/python3.11/site-packages/urllib3/util/util.py:38: in reraise
    raise value.with_traceback(tb)
/opt/computersetup/.pyenv/versions/3.11.6/lib/python3.11/site-packages/urllib3/connectionpool.py:787: in urlopen
    response = self._make_request(
/opt/computersetup/.pyenv/versions/3.11.6/lib/python3.11/site-packages/urllib3/connectionpool.py:493: in _make_request
    conn.request(
/opt/computersetup/.pyenv/versions/3.11.6/lib/python3.11/site-packages/urllib3/connection.py:494: in request
    self.endheaders()
/opt/computersetup/.pyenv/versions/3.11.6/lib/python3.11/http/client.py:1281: in endheaders
    self._send_output(message_body, encode_chunked=encode_chunked)
/opt/computersetup/.pyenv/versions/3.11.6/lib/python3.11/http/client.py:1041: in _send_output
    self.send(msg)
/opt/computersetup/.pyenv/versions/3.11.6/lib/python3.11/http/client.py:979: in send
    self.connect()
../../.local/lib/python3.11/site-packages/docker/transport/unixconn.py:26: in connect
    sock.connect(self.unix_socket)
E   urllib3.exceptions.ProtocolError: ('Connection aborted.', FileNotFoundError(2, 'No such file or directory'))

During handling of the above exception, another exception occurred:
../../.local/lib/python3.11/site-packages/docker/api/client.py:223: in _retrieve_server_version
    return self.version(api_version=False)["ApiVersion"]
           ^^^^^^^^^^^^^^^^^^^^^^^^^^^^^^^
../../.local/lib/python3.11/site-packages/docker/api/daemon.py:181: in version
    return self._result(self._get(url), json=True)
                        ^^^^^^^^^^^^^^
../../.local/lib/python3.11/site-packages/docker/utils/decorators.py:44: in inner
    return f(self, *args, **kwargs)
           ^^^^^^^^^^^^^^^^^^^^^^^^
../../.local/lib/python3.11/site-packages/docker/api/client.py:246: in _get
    return self.get(url, **self._set_request_timeout(kwargs))
           ^^^^^^^^^^^^^^^^^^^^^^^^^^^^^^^^^^^^^^^^^^^^^^^^^^
/opt/computersetup/.pyenv/versions/3.11.6/lib/python3.11/site-packages/requests/sessions.py:602: in get
    return self.request("GET", url, **kwargs)
           ^^^^^^^^^^^^^^^^^^^^^^^^^^^^^^^^^^
/opt/computersetup/.pyenv/versions/3.11.6/lib/python3.11/site-packages/requests/sessions.py:589: in request
    resp = self.send(prep, **send_kwargs)
           ^^^^^^^^^^^^^^^^^^^^^^^^^^^^^^
/opt/computersetup/.pyenv/versions/3.11.6/lib/python3.11/site-packages/requests/sessions.py:703: in send
    r = adapter.send(request, **kwargs)
        ^^^^^^^^^^^^^^^^^^^^^^^^^^^^^^^
/opt/computersetup/.pyenv/versions/3.11.6/lib/python3.11/site-packages/requests/adapters.py:682: in send
    raise ConnectionError(err, request=request)
E   requests.exceptions.ConnectionError: ('Connection aborted.', FileNotFoundError(2, 'No such file or directory'))

The above exception was the direct cause of the following exception:
sologit/engines/test_orchestrator.py:86: in __init__
    self.docker_client = docker.from_env()
                         ^^^^^^^^^^^^^^^^^
../../.local/lib/python3.11/site-packages/docker/client.py:94: in from_env
    return cls(
../../.local/lib/python3.11/site-packages/docker/client.py:45: in __init__
    self.api = APIClient(*args, **kwargs)
               ^^^^^^^^^^^^^^^^^^^^^^^^^^
../../.local/lib/python3.11/site-packages/docker/api/client.py:207: in __init__
    self._version = self._retrieve_server_version()
                    ^^^^^^^^^^^^^^^^^^^^^^^^^^^^^^^
../../.local/lib/python3.11/site-packages/docker/api/client.py:230: in _retrieve_server_version
    raise DockerException(
E   docker.errors.DockerException: Error while fetching server API version: ('Connection aborted.', FileNotFoundError(2, 'No such file or directory'))

During handling of the above exception, another exception occurred:
tests/test_phase3_workflows.py:35: in test_orchestrator
    return TestOrchestrator(git_engine)
           ^^^^^^^^^^^^^^^^^^^^^^^^^^^^
sologit/engines/test_orchestrator.py:90: in __init__
    raise TestOrchestratorError(f"Docker not available: {e}")
E   sologit.engines.test_orchestrator.TestOrchestratorError: Docker not available: Error while fetching server API version: ('Connection aborted.', FileNotFoundError(2, 'No such file or directory'))
------------------------------ Captured log setup ------------------------------
ERROR    sologit.engines.test_orchestrator:test_orchestrator.py:89 Failed to connect to Docker: Error while fetching server API version: ('Connection aborted.', FileNotFoundError(2, 'No such file or directory'))
=================================== FAILURES ===================================
__________ TestGitEngineErrorHandling.test_init_from_git_invalid_url ___________
tests/test_git_engine_100_percent.py:75: in test_init_from_git_invalid_url
    with pytest.raises(GitEngineError) as exc_info:
E   Failed: DID NOT RAISE <class 'sologit.engines.git_engine.GitEngineError'>
__________ TestGitEngineErrorHandling.test_create_workpad_long_title ___________
tests/test_git_engine_100_percent.py:96: in test_create_workpad_long_title
    pad_id = git_engine.create_workpad(repo_id, long_title)
             ^^^^^^^^^^^^^^^^^^^^^^^^^^^^^^^^^^^^^^^^^^^^^^
sologit/engines/git_engine.py:224: in create_workpad
    raise GitEngineError("Workpad title too long (max 100 characters)")
E   sologit.engines.git_engine.GitEngineError: Workpad title too long (max 100 characters)
_______ TestGitEngineErrorHandling.test_create_workpad_repository_error ________
tests/test_git_engine_100_percent.py:120: in test_create_workpad_repository_error
    with pytest.raises(GitEngineError) as exc_info:
E   Failed: DID NOT RAISE <class 'sologit.engines.git_engine.GitEngineError'>
____________ TestGitEngineErrorHandling.test_promote_workpad_error _____________
tests/test_git_engine_100_percent.py:158: in test_promote_workpad_error
    original_merge = Git.merge
                     ^^^^^^^^^
/opt/computersetup/.pyenv/versions/3.11.6/lib/python3.11/site-packages/git/cmd.py:570: in __getattribute
    return super().__getattribute__(name)
           ^^^^^^^^^^^^^^^^^^^^^^^^^^^^^^
E   AttributeError: type object 'Git' has no attribute 'merge'
___________ TestGitEngineErrorHandling.test_revert_last_commit_error ___________
tests/test_git_engine_100_percent.py:178: in test_revert_last_commit_error
    original_reset = Head.reset
                     ^^^^^^^^^^
E   AttributeError: type object 'Head' has no attribute 'reset'
________________ TestGitEngineErrorHandling.test_get_diff_error ________________
tests/test_git_engine_100_percent.py:198: in test_get_diff_error
    original_diff = Git.diff
                    ^^^^^^^^
/opt/computersetup/.pyenv/versions/3.11.6/lib/python3.11/site-packages/git/cmd.py:570: in __getattribute
    return super().__getattribute__(name)
           ^^^^^^^^^^^^^^^^^^^^^^^^^^^^^^
E   AttributeError: type object 'Git' has no attribute 'diff'
_________ TestGitEngineErrorHandling.test_rollback_to_checkpoint_error _________
tests/test_git_engine_100_percent.py:278: in test_rollback_to_checkpoint_error
    original_reset = Head.reset
                     ^^^^^^^^^^
E   AttributeError: type object 'Head' has no attribute 'reset'
____________ TestGitEngineErrorHandling.test_compare_workpads_error ____________
tests/test_git_engine_100_percent.py:458: in test_compare_workpads_error
    original_diff = Git.diff
                    ^^^^^^^^
/opt/computersetup/.pyenv/versions/3.11.6/lib/python3.11/site-packages/git/cmd.py:570: in __getattribute
    return super().__getattribute__(name)
           ^^^^^^^^^^^^^^^^^^^^^^^^^^^^^^
E   AttributeError: type object 'Git' has no attribute 'diff'
____________ TestCreatePatchFromFiles.test_create_patch_repo_error _____________
tests/test_patch_engine_100_percent.py:307: in test_create_patch_repo_error
    with pytest.raises(PatchEngineError) as exc_info:
E   Failed: DID NOT RAISE <class 'sologit.engines.patch_engine.PatchEngineError'>
=============================== warnings summary ===============================
sologit/analysis/test_analyzer.py:55
  /home/ubuntu/code_artifacts/solo-git/sologit/analysis/test_analyzer.py:55: PytestCollectionWarning: cannot collect test class 'TestAnalyzer' because it has a __init__ constructor (from: tests/test_phase3_enhanced_mocks.py)
    class TestAnalyzer:

sologit/analysis/test_analyzer.py:41
  /home/ubuntu/code_artifacts/solo-git/sologit/analysis/test_analyzer.py:41: PytestCollectionWarning: cannot collect test class 'TestAnalysis' because it has a __init__ constructor (from: tests/test_phase3_enhanced_mocks.py)
    @dataclass

sologit/engines/test_orchestrator.py:33
  /home/ubuntu/code_artifacts/solo-git/sologit/engines/test_orchestrator.py:33: PytestCollectionWarning: cannot collect test class 'TestConfig' because it has a __init__ constructor (from: tests/test_phase3_enhanced_mocks.py)
    @dataclass

sologit/engines/test_orchestrator.py:46
  /home/ubuntu/code_artifacts/solo-git/sologit/engines/test_orchestrator.py:46: PytestCollectionWarning: cannot collect test class 'TestResult' because it has a __init__ constructor (from: tests/test_phase3_enhanced_mocks.py)
    @dataclass

sologit/engines/test_orchestrator.py:25
  /home/ubuntu/code_artifacts/solo-git/sologit/engines/test_orchestrator.py:25: PytestCollectionWarning: cannot collect test class 'TestStatus' because it has a __init__ constructor (from: tests/test_phase3_enhanced_mocks.py)
    class TestStatus(Enum):

sologit/engines/test_orchestrator.py:63
  /home/ubuntu/code_artifacts/solo-git/sologit/engines/test_orchestrator.py:63: PytestCollectionWarning: cannot collect test class 'TestOrchestrator' because it has a __init__ constructor (from: tests/test_phase3_workflows.py)
    class TestOrchestrator:

sologit/engines/test_orchestrator.py:33
  /home/ubuntu/code_artifacts/solo-git/sologit/engines/test_orchestrator.py:33: PytestCollectionWarning: cannot collect test class 'TestConfig' because it has a __init__ constructor (from: tests/test_phase3_workflows.py)
    @dataclass

sologit/engines/test_orchestrator.py:25
  /home/ubuntu/code_artifacts/solo-git/sologit/engines/test_orchestrator.py:25: PytestCollectionWarning: cannot collect test class 'TestStatus' because it has a __init__ constructor (from: tests/test_phase3_workflows.py)
    class TestStatus(Enum):

sologit/analysis/test_analyzer.py:41
  /home/ubuntu/code_artifacts/solo-git/sologit/analysis/test_analyzer.py:41: PytestCollectionWarning: cannot collect test class 'TestAnalysis' because it has a __init__ constructor (from: tests/test_promotion_gate.py)
    @dataclass

sologit/analysis/test_analyzer.py:55
  /home/ubuntu/code_artifacts/solo-git/sologit/analysis/test_analyzer.py:55: PytestCollectionWarning: cannot collect test class 'TestAnalyzer' because it has a __init__ constructor (from: tests/test_test_analyzer.py)
    class TestAnalyzer:

sologit/analysis/test_analyzer.py:41
  /home/ubuntu/code_artifacts/solo-git/sologit/analysis/test_analyzer.py:41: PytestCollectionWarning: cannot collect test class 'TestAnalysis' because it has a __init__ constructor (from: tests/test_test_analyzer.py)
    @dataclass

sologit/engines/test_orchestrator.py:46
  /home/ubuntu/code_artifacts/solo-git/sologit/engines/test_orchestrator.py:46: PytestCollectionWarning: cannot collect test class 'TestResult' because it has a __init__ constructor (from: tests/test_test_analyzer.py)
    @dataclass

sologit/engines/test_orchestrator.py:25
  /home/ubuntu/code_artifacts/solo-git/sologit/engines/test_orchestrator.py:25: PytestCollectionWarning: cannot collect test class 'TestStatus' because it has a __init__ constructor (from: tests/test_test_analyzer.py)
    class TestStatus(Enum):

-- Docs: https://docs.pytest.org/en/stable/how-to/capture-warnings.html
================================ tests coverage ================================
_______________ coverage: platform linux, python 3.11.6-final-0 ________________

Name                                       Stmts   Miss  Cover   Missing
------------------------------------------------------------------------
sologit/__init__.py                            3      0   100%
sologit/analysis/__init__.py                   2      0   100%
sologit/analysis/test_analyzer.py            196     19    90%   170, 226, 301-302, 305-306, 309-310, 319-320, 359, 364, 385, 387, 397-400, 402
sologit/api/__init__.py                        0      0   100%
sologit/api/client.py                         87     60    31%   68-69, 72-73, 94-120, 154-195, 230-272
sologit/cli/__init__.py                        0      0   100%
sologit/cli/commands.py                      353    353     0%   8-622
sologit/cli/config_commands.py               135    135     0%   8-224
sologit/cli/main.py                           72     72     0%   9-144
sologit/config/__init__.py                     0      0   100%
sologit/config/manager.py                    154     31    80%   29, 197-200, 250, 252, 256, 260, 267-294, 298, 302, 306-309, 318-338
sologit/config/templates.py                    2      2     0%   7-80
sologit/core/__init__.py                       0      0   100%
sologit/core/repository.py                    32      0   100%
sologit/core/workpad.py                       49      0   100%
sologit/engines/__init__.py                    0      0   100%
sologit/engines/git_engine.py                606     63    90%   201-206, 272-274, 298, 355, 389, 426-428, 456-458, 487-489, 503, 596, 640, 653-655, 673, 703-705, 719, 738-739, 765, 837, 875, 922, 926, 937, 976, 1019, 1052, 1082, 1125, 1129, 1135, 1156, 1158, 1196-1198, 1212, 1276, 1289, 1297-1298, 1337, 1356-1357, 1366, 1380-1381, 1393-1394
sologit/engines/patch_engine.py              209      3    99%   221-223
sologit/engines/test_orchestrator.py         134     81    40%   87, 109-128, 147, 155-167, 176-225, 242-305, 328-331, 335, 339
sologit/orchestration/__init__.py              6      0   100%
sologit/orchestration/ai_orchestrator.py     131      0   100%
sologit/orchestration/code_generator.py      138      0   100%
sologit/orchestration/cost_guard.py          134      3    98%   122-123, 136
sologit/orchestration/model_router.py        133      0   100%
sologit/orchestration/planning_engine.py     114      2    98%   267-268
sologit/utils/__init__.py                      0      0   100%
sologit/utils/logger.py                       63     37    41%   39-40, 43-49, 61-95, 110, 119-121, 124-126, 129
sologit/workflows/__init__.py                  5      0   100%
sologit/workflows/auto_merge.py              133     27    80%   94-96, 107-111, 127, 129, 143-147, 163-169, 185-189, 201
sologit/workflows/ci_orchestrator.py         117     18    85%   100, 122, 153, 168-178, 207-216, 232-235, 257
sologit/workflows/promotion_gate.py          120     24    80%   139, 146-152, 175-179, 184-188, 193-195, 199, 205-206, 227, 240-243
sologit/workflows/rollback_handler.py         91     35    62%   82, 93-125, 145, 187-189, 206-228
------------------------------------------------------------------------
TOTAL                                       3219    965    70%
Coverage HTML written to dir htmlcov
Coverage JSON written to file coverage_baseline.json
=========================== short test summary info ============================
FAILED tests/test_git_engine_100_percent.py::TestGitEngineErrorHandling::test_init_from_git_invalid_url - Failed: DID NOT RAISE <class 'sologit.engines.git_engine.GitEngineError'>
FAILED tests/test_git_engine_100_percent.py::TestGitEngineErrorHandling::test_create_workpad_long_title - sologit.engines.git_engine.GitEngineError: Workpad title too long (max 100 characters)
FAILED tests/test_git_engine_100_percent.py::TestGitEngineErrorHandling::test_create_workpad_repository_error - Failed: DID NOT RAISE <class 'sologit.engines.git_engine.GitEngineError'>
FAILED tests/test_git_engine_100_percent.py::TestGitEngineErrorHandling::test_promote_workpad_error - AttributeError: type object 'Git' has no attribute 'merge'
FAILED tests/test_git_engine_100_percent.py::TestGitEngineErrorHandling::test_revert_last_commit_error - AttributeError: type object 'Head' has no attribute 'reset'
FAILED tests/test_git_engine_100_percent.py::TestGitEngineErrorHandling::test_get_diff_error - AttributeError: type object 'Git' has no attribute 'diff'
FAILED tests/test_git_engine_100_percent.py::TestGitEngineErrorHandling::test_rollback_to_checkpoint_error - AttributeError: type object 'Head' has no attribute 'reset'
FAILED tests/test_git_engine_100_percent.py::TestGitEngineErrorHandling::test_compare_workpads_error - AttributeError: type object 'Git' has no attribute 'diff'
FAILED tests/test_patch_engine_100_percent.py::TestCreatePatchFromFiles::test_create_patch_repo_error - Failed: DID NOT RAISE <class 'sologit.engines.patch_engine.PatchEngineError'>
ERROR tests/test_phase3_workflows.py::TestAutoMergeWorkflow::test_workflow_initialization - sologit.engines.test_orchestrator.TestOrchestratorError: Docker not available: Error while fetching server API version: ('Connection aborted.', FileNotFoundError(2, 'No such file or directory'))
ERROR tests/test_phase3_workflows.py::TestAutoMergeWorkflow::test_workflow_with_custom_rules - sologit.engines.test_orchestrator.TestOrchestratorError: Docker not available: Error while fetching server API version: ('Connection aborted.', FileNotFoundError(2, 'No such file or directory'))
ERROR tests/test_phase3_workflows.py::TestAutoMergeWorkflow::test_execute_nonexistent_workpad - sologit.engines.test_orchestrator.TestOrchestratorError: Docker not available: Error while fetching server API version: ('Connection aborted.', FileNotFoundError(2, 'No such file or directory'))
ERROR tests/test_phase3_workflows.py::TestAutoMergeWorkflow::test_format_result - sologit.engines.test_orchestrator.TestOrchestratorError: Docker not available: Error while fetching server API version: ('Connection aborted.', FileNotFoundError(2, 'No such file or directory'))
ERROR tests/test_phase3_workflows.py::TestCIOrchestrator::test_orchestrator_initialization - sologit.engines.test_orchestrator.TestOrchestratorError: Docker not available: Error while fetching server API version: ('Connection aborted.', FileNotFoundError(2, 'No such file or directory'))
ERROR tests/test_phase3_workflows.py::TestCIOrchestrator::test_run_smoke_tests_nonexistent_repo - sologit.engines.test_orchestrator.TestOrchestratorError: Docker not available: Error while fetching server API version: ('Connection aborted.', FileNotFoundError(2, 'No such file or directory'))
ERROR tests/test_phase3_workflows.py::TestCIOrchestrator::test_format_ci_result - sologit.engines.test_orchestrator.TestOrchestratorError: Docker not available: Error while fetching server API version: ('Connection aborted.', FileNotFoundError(2, 'No such file or directory'))
============ 9 failed, 376 passed, 13 warnings, 7 errors in 20.46s =============
